Workbook

Sheet README
B3: Please contact Bart Lorang (lorangb@gmail.com or 303.717.0414) to discuss this model and walk through it.
B5: Instructions
B6: -Cells in Yellow are Assumptions, where feasible, sources are noted
B7: *Net Present Value is calculated based on CEMEX's WACC from their public financials. This is how public company finance departments (partiuclarly mining organizations) evaluate projects
B8: *Proposal Matrix sheet Stacks up the Town of Lyons Proposal vs. current options on the table
B10: Disclaimers
B11: * This is an outside-in financial pro-forma based on a wide range of assumptions.
B12: * If there's a bug in a formula, or something needs to be cleaned up, please don't hesitate to make it happen
B13: * Everything isn't perfect, this is all "v0.1"
B14: * Water Rights information if highly speculative at best, and is sourced from a 1977 Mining Reclamation Plan document detailing CEMEX's water rights south of HWY 66

Sheet NPVs & Pro-Formas
B2: Summary - Value to Shareholders for CEMEX | C2: Net Present Value | D2: CEMEX's Preference
B3: =B60 -> Option A - Stop Mining, Operate "Plant Indefinitely" | C3: =C94 -> -3237342.5 | D3: 4
B4: =B100 -> Option B - Operate 15 Years, then Shut Down, Sell to BoCo | C4: =C131 -> 64432187 | D4: 1
B5: =B135 -> Option C - Operate 5 Years, Land Conserved, Purchase Options to Boulder/Lyons | C5: =C174 -> 40720124 | D5: 2
B6: =B178 -> Option D - Stop Mining If Permit Denied, Sell Off All Assets | C6: =C178 -> 23291773 | D6: 3
B8: Key Assumptions
B10: Capital Costs
B11: Discount Rate (WACC) for CEMEX | C11: 0.145 | D11: <-- from https://finbox.com/NYSE:CX/explorer/wacc
B13: Reclamation & Cleanup Costs
B14: Dowe Flats Reclamation Costs | C14: -12683299 | D14: <-- from surety bonds (https://drms.colorado.gov/search-by-county)
B15: Cement Mine/Plant Reclamation Costs ("Lyons Quarry") | C15: -8953127 | D15: <-- surety bonds (https://drms.colorado.gov/search-by-county)
B16: CEMEX Sandstone Quarry Reclamation Costs | C16: -409366 | D16: <-- from surety bonds (https://drms.colorado.gov/search-by-county)
B17: CEMEX Plant Demolition Costs (Additional above and beyond 20 year old estimates) | C17: -15000000 | D17: <-- need to estimate what it would cost to safely tear it down and haul it away
B19: Production & Raw Materials Assumptions
B20: Tons of Limestone Trucked In Per Year (from Unknown Location) | C20: 250000 | D20: <~ according to applicants (confusing) testimony, this is happening already at 300,0i00 (assume 250K limestone and 50K shale?)
B21: Tons of Limestone Dowe Flats Produces Per Year | C21: 50000 | D21: < -- assumption based on CEMEX (confusing) testimony
B22: Tons of Shale Dowe Flats Produces Per Year | C22: 350000 | D22: <--400,000 per year according to CEMEX (although CEMEX SU-22-003 application had <300,000 per year) Applicant Testified at 350,000 - 450,000
B23: Tons of Silica Hauled from Silica Quarry | C23: 35000 | D23: <-- from CEMEX Application SU-22-003
B24: Ratio of Raw Material (Limestone, Shale) for 1 Ton of Cement | C24: 1.7 | D24: <-- from research of typical ratios
B25: Implied Tons of Cement Per Year (based on Limestone+Silica+Shale) | C25: 338475 | D25: <-- calculation/estimate - other data from https://www.sec.gov/Archives/edgar/data/1076378/000119312522133730/0001193125-22-133730-index.html indicates 338,475 in 2021
B26: Total Raw Material Tonnage (Limestone, Shale and Silica) | C26: =C20+C22+C23+C21 -> 685000 | D26: <-- calculation (Applicant said 700,000 to 750,000 tons)
B28: Pricing Assumptions
B29: Cement Price (2022) | C29: 134 | D29: <-- from research - https://www.ibisworld.com/us/bed/price-of-cement/190/ - need to validate with price quote from CEMEX Lyons
B30: Annual Price Increase (Cement + Transportation) | C30: 0.035 | D30: <-- Estimated Price Escalator Rate (Inflation, which is currently at 8.5% in May 2022)
B31: Net Operating Margin | C31: 0.19 | D31: <--based on CEMEX USA SEC public filings, although CEMEX Lyons could be higher/lower
B33: Transporation/Shipping Costs
B34: Miles for Shipment (from Southern Wyoming) | C34: 60 | D34: <-- estimated distance driven in miles
B35: Cost Per Ton-Mile (2022) | C35: 0.22 | D35: <-- https://www.bts.gov/content/average-freight-revenue-ton-mile | H35: http://cemexclaytonquarry.com/#s_2
B36: Cost for 80 ton, 18-wheeler, round-trip of 75 tons of raw material to and from location | C36: =C35*C34*75 -> 990 | D36: <-- calculation
B37: Increased Cost Per Ton of Raw Materials from 3rd party | C37: =0.35*40 -> 14 | D37: <-- based on simply 35% gross profit margin on Limestone or Silica, @ $40/ton
B38: Effective Price Increase Per Ton based on Transportation/Shipping | C38: =C34*C35 -> 13.2 | D38: <-- computed
B39: Relative Price Increase Per Ton based on Transporation/Shipping | C39: =C38/C29 -> 0.098507463 | D39: <-- computed
B41: Real Estate Transaction Assumptions
B42: Boulder County's Price - CEMEX Land Surrounding Plant Price Per Acre | C42: 17000 | D42: <--based on CEMEX proposal to Boulder County in 2022, escalating 2% per year
B43: Boulder County's Price - CEMEX Plant Site, Price Per Acre (60 Acres) | C43: 250000 | D43: <-- Estimate (what is fair market value per acre for General Industrial land - $250,000/acre)
B44: Boulder County's Price - Dowe Flats (208 Acre Plot) Value Per Acre | C44: 17000
B45: Boulder County's Price - Land Apprecation Rate | C45: 0.02 | D45: <-- what seems to be negotiated by Boulder County transactions
B46: Boulder County's Price - Conservation Easement Price Per Acre | C46: 2413.2535
B48: Fair Market Value - CEMEX Surrounding Plant Price Per Acre (830 Acres unencumbered) | C48: 40000 | D48: <-- Estimate (what is fair market value per acre that is NOT incumbered with a Conservation Easement)
B49: Fair Market Value - CEMEX Plant Site Land (60 Acres w/ Structures Included, zoned General Industrial) | C49: =250000 -> 250000 | D49: <-- Estimate (what is fair market value per acre for General Industrial land - $250,000/acre)
...

Sheet Proposal Matrix
B2: Key Deal Terms & Benefits | C2: Option A Status Quo "Possibly Indefinite" | D2: Option B CEMEX Proposal "15 Years More Mining" | E2: Option C Town of Lyons Proposal "5 Years More Mining" | F2: Option D (CEMEX's BATNA) CEMEX Stops Production, Sells Assets to Highest Bidder
B4: CEMEX Gets:
B5: - Dowe Flats Mining Extension | C5: 0 Years | D5: 15 Years | E5: 5 Years
B6: - Continued Plant Operation | C6: Permitted Indefinitely | D6: 15 Years | E6: 5 Years
B7: - Estimated Net Present Value for CEMEX (e.g. Value for Shareholders) | C7: ='NPVs & Pro-Formas'!C3 -> -3237342.5 | D7: ='NPVs & Pro-Formas'!C4 -> 64432187 | E7: ='NPVs & Pro-Formas'!C5 -> 40720124 | F7: =#REF! -> #REF!
B8: - Profitable & Sustainable Ongoing Operation | C8: No | D8: Yes | E8: Yes | F8: No
B9: - NEW: Graceful Exit and Wind Down from Boulder County | C9: No | D9: No | E9: Yes | F9: No
B11: CEMEX Gives:
B12: - Purchase Options @ $17,000/acre on Land Surrounding Plant (830 Acres) | C12: No | D12: Yes - to Boulder County | E12: Yes - to Boulder (~60%), Lyons (~40%)
B13: - NEW: Purchase Options @ $17,000/acre on remaining CEMEX Area incl Plant (~100 Acres) | C13: No | D13: No | E13: Yes - to Lyons
B14: - NEW: Updated IGA for Land Use (Covenant / Conservation Easement) on CEMEX Area (930 Acres) | C14: No | D14: No | E14: Yes - w/ Boulder County & Lyons
B15: - NEW: Commitment to Close Plant | C15: No | D15: Yes - by 2037 | E15: Yes - by 2027
B16: - NEW: Demolish Plant and Perform Cleanup/Reclamation | C16: Indeterminate | D16: Indeterminate | E16: by 2030
B17: - Reclaim Dowe Flats | C17: by 2025 | D17: by 2041 | E17: by 2030
B18: - Reclaim Land surrounding Plant | C18: Indeterminate | D18: by 2041 | E18: by 2030
B19: - Provide Trail Easement for St Vrain Greenway | C19: No | D19: Yes | E19: Yes
B20: - NEW: Commitment best attempts to sequester C02 Emissions | C20: No | D20: No | E20: Yes
B21: - NEW: Commitment best attempts to mitigate ongoing Noise, Light & Dust pollution | C21: No | D21: No | E21: Yes
B22: - NEW: Lyons and/or Boulder County Right of First Refusal on Any Water Rights Sales | C22: No | D22: No | E22: Yes
B24: Boulder County Gets:
B25: -NEW: Climate Goals: Annual Reduction of C02 by 2030 | C25: 0 | D25: 0 | E25: 357,000 Tons/Yr (12.5% of 2030 Goal) | F25: 350,000 Tons (12.5% of 2030 Goal)
B26: - Addtl Acres of Protected Open Space and/or Conserved Land | C26: =SUM(C27:C28) -> 766 | D26: =SUM(D27:D28) -> 1804 | E26: =SUM(E27:E28) -> 1904 | F26: =SUM(F27:F28) -> 766
B27: - Addtl Acres of Open Space | C27: 766 | D27: 1804 | E27: =766+208+510 -> 1484 | F27: 766
B28: - NEW: Addtl Acres governed by Covenenant / Conservation Easement (75% minimum CE) | C28: 0 | D28: 0 | E28: 420 | F28: 0
B29: - Total Amount Spent | C29: 7150000 | D29: 8000000 | E29: ='NPVs & Pro-Formas'!C175 -> 3840400
B30: - NEW: Updated IGA for Land Use (Covenant / Conservation Easement) on entire CEMEX Area (930 Acres) | C30: No | D30: No - 830 Acres | E30: Yes - 930 Acres
B31: - Purchase Options to acquire ~510 Acres Open Space @ $17,000 / acre | C31: No | D31: Yes - 830 Acres | E31: Yes - 510 Acres
B32: - NEW: Purchase Options to acquire ~420 Acres CEMEX Area after 2035 if not Exercised/Annexed by Lyons | C32: No | D32: No | E32: Yes
B33: - Cement Plant Closes (*) | C33: No | D33: Yes (2037) | E33: Yes (2027) | F33: No
B34: - NEW: Cessation of General Industrial Activity at CEMEX Plant Site and Zoning Change | C34: No | D34: No | E34: Yes (2030) | F34: No
B35: - NEW: Plant Demolished and Plant Site Cleaned Up | C35: No | D35: No | E35: Yes (2030) | F35: No
B36: - NEW: Improved Beauty of St. Vrain Valley / "Gateway to the Rockies" | C36: No | D36: No | E36: Yes | F36: No
B37: - Trail Easement for St Vrain Greenway | C37: No | D37: Yes | E37: Yes
B38: - Access Easement to Boulder County property | C38: No | D38: Yes | E38: Yes
B39: - NEW Credit/Accolades for Transforming a Brown Field Into a Best-In-Class Eco Community | C39: No | D39: No | E39: Yes
B41: Town of Lyons Gets
B42: - NEW: Updated IGA for Land Use (Covenant / Conservation Easement) on entire CEMEX Area (930 Acres) | C42: No | D42: No - 830 Acres | E42: Yes - 930 Acres
B43: - Options to Develop portion of CEMEX Area for Low-Density Sustainable Mixed-Use (spirit of 2012 IGA) | C43: No | D43: No | E43: Yes | F43: No
B44: - Options to Develop Municipal Facility for 100% Renewable Energy (spirit of 2012 IGA) | C44: No | D44: No | E44: Yes
B45: - NEW: Purchase Options & 5yr window to Annex/Solicit Plans for ~420 Acres CEMEX Area (2030 to 2035) @ $17,000 per acre | C45: No | D45: No | E45: Yes
...

Sheet Water Rights
F1: 1 cfs = | G1: 1.9834711 | H1: acre-feet per day
B2: Source: 1977 Lyons Plant Reclamation Plan - Permit M77208
F3: unit | G3: days a year available | I3: acre-feet/yr equivalent | K3: acre-foot pricing / market | L3: value
B4: 1. Outlet ditch and outlet pipeline | E4: 6.4 | F4: cfs | G4: =180 -> 180 | I4: =E4*$G$1*G4 -> 2284.9587 | K4: 1000 | L4: =I4*K4 -> 2284958.7
B5: 2. Martin Marietta east seepage ditch | E5: 1 | F5: cfs | G5: =180 -> 180 | I5: =E5*$G$1*G5 -> 357.0248 | K5: 1000 | L5: =I5*K5 -> 357024.8
B6: 3. Martin Marietta tile drain | E6: 1.5 | F6: cfs | G6: =180 -> 180 | I6: =E6*$G$1*G6 -> 535.5372 | K6: 1000 | L6: =I6*K6 -> 535537.2
B7: 4. Martin Marietta cement lake | C7: *(stoarage and recreational)(= | E7: 36 | F7: acre-feet | G7: 365 | K7: 0 | L7: =I7*K7 -> 0
B8: 5. Kimball Lake | E8: 20 | F8: acre-feet | G8: 365 | K8: 0 | L8: =I8*K8 -> 0
B9: 6. Smead Ditch | E9: 4 | F9: cfs | G9: 180 | I9: =E9*$G$1*G9 -> 1428.0992 | K9: 1000 | L9: =I9*K9 -> 1428099.2
B10: 7. Swede Ditch | E10: 1.675 | F10: cfs | G10: 180 | I10: =E10*$G$1*G10 -> 598.01654 | K10: 1000 | L10: =I10*K10 -> 598016.54
B11: 8. South Ledge | E11: 14.32 | F11: cfs | G11: 180 | I11: =E11*$G$1*G11 -> 5112.5951 | K11: 1000 | L11: =I11*K11 -> 5112595.1
B12: 9. Big Thompson water | E12: 55 | F12: acre-feet | G12: 1 | I12: =E12*G12 -> 55 | K12: 75000 | L12: =I12*K12 -> 4125000
B13: 10. Dowe Flats Water (1993 Permit) | E13: 150000 | F13: gallons-day | G13: 1 | I13: =0.55*365 -> 200.75 | K13: 10000 | L13: =I13*K13 -> 2007500
B15: Totals | I15: =SUM(I4:I13) -> 10571.982 | K15: =L15/I15 -> 1555.8797 | L15: =SUM(L4:L13) -> 16448732
