Workbook

Sheet Chart
M2: Landis Report
B26: Timeframe | C26: Material | D26: External or Local | E26: Transport Mode | F26: Vehicle Miles | G26: Avg Tons / Year | H26: Distance Miles | I26: Source
B27: Oct 1, 2022 to Present | C27: Limestone | D27: External (State/County Roads) | E27: 25 Ton Highway Trucks | F27: =G27*H27/25*2 -> 2520000 | G27: 350000 | H27: 90 | I27: Weaver Mine, Laramie Wyoming
C28: Shale | D28: External (State/County Roads) | E28: 25 Ton Highway Trucks | F28: =G28*H28/25*2 -> 980000 | G28: 350000 | H28: 35 | I28: Arcosa Lightweight, 11728 Highway 93, Boulder, CO
B29: Sep 18, 2018 to Sep 30, 2022 | C29: Limestone | D29: External | E29: 25 Ton Highway Trucks | F29: =G29*H29/25*2 -> 2520000 | G29: 350000 | H29: 90 | I29: Weaver Mine, Laramie Wyoming
C30: Shale | D30: Local (Haul Roads) | E30: Conveyor | F30: N/A | G30: 350000 | H30: 1.5 | I30: Dowe Flats Mine, crossing Highway 66
B31: August 18, 1997 to Sep 17, 2022 | C31: LImestone | D31: Local (Haul Roads) | E31: Conveyor | F31: N/A | G31: 350000 | H31: 1.5 | I31: Dowe Flats Mine, crossing Highway 66
C32: Shale | D32: Local (Haul Roads) | E32: Conveyor | F32: N/A | G32: 350000 | H32: 1.5 | I32: Dowe Flats Mine, crossing Highway 66
B33: January 1997 to August 18th, 1997 | C33: LImestone | D33: Local (Haul Roads) | E33: 85 Ton Haul Road Trucks | F33: N/A | G33: 350000 | H33: 1 | I33: Lyons Quarry (Pits A, B, C, D, E)
C34: Shale | D34: Local (Haul Roads) | E34: 85 Ton Haul Road Trucks | F34: N/A | G34: 350000 | H34: 1 | I34: Lyons Quarry (Pits A, B, C, D, E)
B35: [1993] to January, 1997 | C35: Limestone | D35: External (State/County Roads) | E35: 25 Ton Highway Trucks | F35: =G35*H35/25*2 -> 132000 | G35: =6000*25 -> 150000 | H35: 11 | I35: Larimer County Quarry
C36: Shale | D36: Local (Haul Roads) | E36: 85 Ton Haul Road Trucks | F36: N/A | G36: 550000 | H36: 1 | I36: Lyons Quarry (Pits A, B, C, D, E)
B37: [1969] to [1993] | C37: Limestone | D37: Local (Haul Roads) | E37: 85 Ton Haul Road Trucks | F37: N/A | G37: 350000 | H37: 1 | I37: Lyons Quarry (Pits A, B, C, D, E)
C38: Shale | D38: Local (Haul Roads) | E38: 85 Ton Haul Road Trucks | F38: N/A | G38: 350000 | H38: 1 | I38: Lyons Quarry (Pits A, B, C, D, E)

Sheet Data
A1: s
A2: Key Assumptions | D2: Intercept Value | E2: Significance | G2: Legend - Sources
A3: Computing Raw Materials from Clinker Production | C3: 1.6009 | D3: 7694.7491 | E3: R^2 of 0.97 and p-value of 0.000 | G3: Landis Report - Reported
A4: Historical Tons Per Inbound Truck (25 Ton Trucks) | C4: 25 | G4: Landis Report - Calculated
A5: Historical Tons Per Outbound Truck (25 Ton Trucks) | C5: 25 | G5: CDPHE - Reported Data
A6: Working Days Per Yeare for ADT (Average Daily Trips) | C6: 250 | G6: Unknown Data
A7: CDOT Multiplier Factor for Heavy Trucks to ADTs using PCE (Passenger Car Equivalent) | C7: 3 | G7: Good Neighbors - Calculated
A8: Roundtrip ADT Factor (Count Arrival & Departure) | C8: 2 | G8: Good Neighbors - Estimate
A10: Year | B10: Timeline of Key Events | C10: Clinker Production (tons) | D10: Raw Material Kiln Feed (tons) | E10: Total ADTs - Average Daily Trips (Calculated) | F10: Trucked In Raw Material (Larimer, Wyoming, Arcosa, Sandstone Mines) | G10: Conveyed or Hauled Raw Material (Dowe Flats or Lyons Quarry) | H10: Source | I10: Truck Volume (Inbound & Outbound) - Landis | J10: Total Trucks (Inbound & Outbound) - GNL | K10: Inbound Trucks (Raw Material) | L10: Inbound ADTs (Raw Material) | M10: Outbound Trucks (Finished Product) | N10: Outbound ADTs (Finished Product) | O10: ADT Change Compared to 1994 (When Noncomforing Use Came Into Effect) | P10: Clinker Tons Per Outbound Truck | Q10: Tons Raw Material Per Inbound Truck
A11: 2023 | B11: CEMEX fined $357K for Air Quality violations for April 2020 to May 2021 | C11: 289021 | D11: =C11*$C$3+$D$3 -> 470388.47 | E11: =L11+N11 -> 729.03309 | F11: =D11 -> 470388.47 | G11: =D11-F11 -> 0 | H11: Calculated - Landis Report | I11: 20106 | J11: =K11+M11 -> 30376.379 | K11: =D11/$C$4 -> 18815.539 | L11: =K11/$C$6*$C$7*$C$8 -> 451.57293 | M11: =C11/$C$5 -> 11560.84 | N11: =M11/$C$6*$C$7*$C$8 -> 277.46016 | O11: =E11-$E$21 -> 472.42509 | P11: =C11/M11 -> 25 | Q11: =D11/K11 -> 25
A12: 2022 | B12: Dowe Flat Closes - September 30th, 2022 | C12: 336085 | D12: =C12*$C$3+$D$3 -> 545733.23 | E12: =L12+N12 -> 591.84 | F12: =K12*$C$4 -> 233100 | G12: =D12-F12 -> 312633.23 | H12: Actuals - Landis Report | I12: 24660 | J12: =K12+M12 -> 24660 | K12: 9324 | L12: =K12/$C$6*$C$7*$C$8 -> 223.776 | M12: =I12-K12 -> 15336 | N12: =M12/$C$6*$C$7*$C$8 -> 368.064 | O12: =E12-$E$21 -> 335.232 | P12: =C12/M12 -> 21.914776 | Q12: =D12/K12 -> 58.529947
A13: 2021 | C13: 341316 | D13: =C13*$C$3+$D$3 -> 554107.53 | E13: =L13+N13 -> 558.648 | F13: =K13*$C$4 -> 245950 | G13: =D13-F13 -> 308157.53 | H13: Actuals - Landis Report | I13: 23277 | J13: =K13+M13 -> 23277 | K13: 9838 | L13: =K13/$C$6*$C$7*$C$8 -> 236.112 | M13: 13439 | N13: =M13/$C$6*$C$7*$C$8 -> 322.536 | O13: =E13-$E$21 -> 302.04 | P13: =C13/M13 -> 25.397425 | Q13: =D13/K13 -> 56.323189
A14: 2020 | C14: 388572 | D14: 605800 | E14: =L14+N14 -> 683.544 | F14: =K14*$C$4 -> 324150 | G14: =D14-F14 -> 281650 | H14: Actuals - Landis Report | I14: 28481 | J14: =K14+M14 -> 28481 | K14: 12966 | L14: =K14/$C$6*$C$7*$C$8 -> 311.184 | M14: =I14-K14 -> 15515 | N14: =M14/$C$6*$C$7*$C$8 -> 372.36 | O14: =E14-$E$21 -> 426.936 | P14: =C14/M14 -> 25.044924 | Q14: =D14/K14 -> 46.722197
A15: 2019 | C15: 279546 | D15: 517217 | E15: =L15+N15 -> 467.472 | F15: =K15*$C$4 -> 170175 | G15: =D15-F15 -> 347042 | H15: Actuals - Landis Report | I15: 19478 | J15: =K15+M15 -> 19478 | K15: 6807 | L15: =K15/$C$6*$C$7*$C$8 -> 163.368 | M15: 12671 | N15: =M15/$C$6*$C$7*$C$8 -> 304.104 | O15: =E15-$E$21 -> 210.864 | P15: =C15/M15 -> 22.061874 | Q15: =D15/K15 -> 75.983106
A16: 2018 | B16: CEMEX Acquires Weaver Mine in Wyoming - Sep 14, 2018 | C16: 313276 | D16: =C16*$C$3+$D$3 -> 509218.3 | E16: =L16+N16 -> 349.368 | F16: =K16*$C$4 -> 26025 | G16: =D16-F16 -> 483193.3 | H16: Actuals - Landis Report | I16: 14557 | J16: =K16+M16 -> 14557 | K16: 1041 | L16: =K16/$C$6*$C$7*$C$8 -> 24.984 | M16: 13516 | N16: =M16/$C$6*$C$7*$C$8 -> 324.384 | O16: =E16-$E$21 -> 92.76 | P16: =C16/M16 -> 23.178159 | Q16: =D16/K16 -> 489.16263
A17: 2017 | C17: 370385 | D17: 566401 | E17: =L17+N17 -> 343.92 | F17: =K17*$C$4 -> 15175 | G17: =D17-F17 -> 551226 | H17: Actuals - Landis Report | I17: 14330 | J17: =K17+M17 -> 14330 | K17: 607 | L17: =K17/$C$6*$C$7*$C$8 -> 14.568 | M17: =I17-K17 -> 13723 | N17: =M17/$C$6*$C$7*$C$8 -> 329.352 | O17: =E17-$E$21 -> 87.312 | P17: =C17/M17 -> 26.99009 | Q17: =D17/K17 -> 933.11532
A18: 2016 | C18: 275799 | D18: 512856 | E18: =L18+N18 -> 271.32 | F18: =K18*$C$4 -> 19950 | G18: =D18-F18 -> 492906 | H18: Actuals - Landis Report | I18: 11305 | J18: =K18+M18 -> 11305 | K18: 798 | L18: =K18/$C$6*$C$7*$C$8 -> 19.152 | M18: =I18-K18 -> 10507 | N18: =M18/$C$6*$C$7*$C$8 -> 252.168 | O18: =E18-$E$21 -> 14.712 | P18: =C18/M18 -> 26.249072 | Q18: =D18/K18 -> 642.67669
A19: 2015 | B19: CEMEX installs better polution equipment | C19: 244074 | D19: 424996 | E19: =L19+N19 -> 209.496 | F19: =K19*$C$4 -> 15975 | G19: =D19-F19 -> 409021 | H19: Actuals - Landis Report | I19: 8729 | J19: =K19+M19 -> 8729 | K19: 639 | L19: =K19/$C$6*$C$7*$C$8 -> 15.336 | M19: 8090 | N19: =M19/$C$6*$C$7*$C$8 -> 194.16 | O19: =E19-$E$21 -> -47.112 | P19: =C19/M19 -> 30.169839 | Q19: =D19/K19 -> 665.09546
A20: 2014 | C20: 381810 | D20: 441253 | E20: =L20+N20 -> 230.448 | F20: =K20*$C$4 -> 29100 | G20: =D20-F20 -> 412153 | H20: Actuals - Landis Report | I20: 9602 | J20: =K20+M20 -> 9602 | K20: 1164 | L20: =K20/$C$6*$C$7*$C$8 -> 27.936 | M20: =I20-K20 -> 8438 | N20: =M20/$C$6*$C$7*$C$8 -> 202.512 | O20: =E20-$E$21 -> -26.16 | P20: =C20/M20 -> 45.248874 | Q20: =D20/K20 -> 379.08333
A21: 2013 | B21: CEMEX settles with EPA for $1M & Agreement to Install Better Pollution Controls | C21: 341377 | D21: 552638 | E21: =L21+N21 -> 256.608 | F21: =K21*$C$4 -> 47100 | G21: =D21-F21 -> 505538 | H21: Actuals - Landis Report | I21: =K21+M21 -> 10692 | J21: =K21+M21 -> 10692 | K21: 1884 | L21: =K21/$C$6*$C$7*$C$8 -> 45.216 | M21: 8808 | N21: =M21/$C$6*$C$7*$C$8 -> 211.392 | O21: =E21-$E$21 -> 0 | P21: =C21/M21 -> 38.757607 | Q21: =D21/K21 -> 293.33227
A22: 2012 | C22: 360763 | D22: 591421 | E22: =L22+N22 -> 270.288 | F22: =K22*$C$4 -> 55850 | G22: =D22-F22 -> 535571 | H22: Actuals - Landis Report | I22: =K22+M22 -> 11262 | J22: =K22+M22 -> 11262 | K22: 2234 | L22: =K22/$C$6*$C$7*$C$8 -> 53.616 | M22: 9028 | N22: =M22/$C$6*$C$7*$C$8 -> 216.672 | O22: =E22-$E$21 -> 13.68 | Q22: =D22/K22 -> 264.73635
A23: 2011 | C23: 390132 | D23: 648369 | E23: =L23+N23 -> 247.584 | F23: =K23*$C$4 -> 24450 | G23: =D23-F23 -> 623919 | H23: Actuals - Landis Report | I23: =K23+M23 -> 10316 | J23: =K23+M23 -> 10316 | K23: 978 | L23: =K23/$C$6*$C$7*$C$8 -> 23.472 | M23: 9338 | N23: =M23/$C$6*$C$7*$C$8 -> 224.112 | O23: =E23-$E$21 -> -9.024 | P23: =C23/M23 -> 41.778968 | Q23: =D23/K23 -> 662.95399
A24: 2010 | C24: 321788 | D24: 541079 | E24: =L24+N24 -> 240.576 | F24: =K24*$C$4 -> 18350 | G24: =D24-F24 -> 522729 | H24: Actuals - Landis Report | I24: =K24+M24 -> 10024 | J24: =K24+M24 -> 10024 | K24: 734 | L24: =K24/$C$6*$C$7*$C$8 -> 17.616 | M24: 9290 | N24: =M24/$C$6*$C$7*$C$8 -> 222.96 | O24: =E24-$E$21 -> -16.032 | P24: =C24/M24 -> 34.638105 | Q24: =D24/K24 -> 737.16485
A25: 2009 | B25: CEMEX settles with State of Colorado for $600K and Air Quality Improvements | C25: 281906 | D25: 463398 | E25: =L25+N25 -> 235.176 | F25: =K25*$C$4 -> 9800 | G25: =D25-F25 -> 453598 | H25: Actuals - Landis Report | I25: =K25+M25 -> 9799 | J25: =K25+M25 -> 9799 | K25: 392 | L25: =K25/$C$6*$C$7*$C$8 -> 9.408 | M25: 9407 | N25: =M25/$C$6*$C$7*$C$8 -> 225.768 | O25: =E25-$E$21 -> -21.432 | P25: =C25/M25 -> 29.967684 | Q25: =D25/K25 -> 1182.1378
A26: 2008 | C26: 311302 | D26: 501317 | E26: =L26+N26 -> 427.32 | F26: =K26*$C$4 -> 25875 | G26: =D26-F26 -> 475442 | H26: Actuals - Landis Report | I26: =K26+M26 -> 17805 | J26: =K26+M26 -> 17805 | K26: 1035 | L26: =K26/$C$6*$C$7*$C$8 -> 24.84 | M26: 16770 | N26: =M26/$C$6*$C$7*$C$8 -> 402.48 | O26: =E26-$E$21 -> 170.712 | P26: =C26/M26 -> 18.563029 | Q26: =D26/K26 -> 484.36425
A27: 2007 | B27: Department of Justice and EPA Sue CEMEX for "Major Modifications" - $10M Expansion Project | C27: 479225 | D27: 788780 | E27: =L27+N27 -> 504.192 | F27: =K27*$C$4 -> 23750 | G27: =D27-F27 -> 765030 | H27: Actuals - Landis Report | I27: =K27+M27 -> 21008 | J27: =K27+M27 -> 21008 | K27: 950 | L27: =K27/$C$6*$C$7*$C$8 -> 22.8 | M27: 20058 | N27: =M27/$C$6*$C$7*$C$8 -> 481.392 | O27: =E27-$E$21 -> 247.584 | P27: =C27/M27 -> 23.891963 | Q27: =D27/K27 -> 830.29474
A28: 2006 | B28: State of Colorado Files Action | C28: 466173 | D28: 734456 | E28: =L28+N28 -> 466.344 | F28: =K28*$C$4 -> 23875 | G28: =D28-F28 -> 710581 | H28: Actuals - Landis Report | I28: =K28+M28 -> 19431 | J28: =K28+M28 -> 19431 | K28: 955 | L28: =K28/$C$6*$C$7*$C$8 -> 22.92 | M28: 18476 | N28: =M28/$C$6*$C$7*$C$8 -> 443.424 | O28: =E28-$E$21 -> 209.736 | P28: =C28/M28 -> 25.231273 | Q28: =D28/K28 -> 769.06387
A29: 2005 | C29: 440384 | D29: 739260 | E29: =L29+N29 -> 439.207 | F29: =$C$4*K29 -> 25000 | G29: =D29-F29 -> 714260 | H29: Landis Report | I29: Missing | J29: =K29+M29 -> 18615.36 | K29: 1000 | L29: =K29/365*2*3 -> 16.438356 | M29: =C29/$C$5 -> 17615.36 | N29: =M29/$C$6*$C$7*$C$8 -> 422.76864 | O29: =E29-$E$21 -> 182.599 | P29: =C29/M29 -> 25 | Q29: =D29/K29 -> 739.26
A30: 2004 | C30: 472053 | D30: 791866 | E30: =L30+N30 -> 469.60924 | F30: =$C$4*K30 -> 25000 | G30: =D30-F30 -> 766866 | H30: Landis Report | I30: Missing | J30: =K30+M30 -> 19882.12 | K30: 1000 | L30: =K30/365*2*3 -> 16.438356 | M30: =C30/$C$5 -> 18882.12 | N30: =M30/$C$6*$C$7*$C$8 -> 453.17088 | O30: =E30-$E$21 -> 213.00124 | P30: =C30/M30 -> 25 | Q30: =D30/K30 -> 791.866
A31: 2003 | C31: 516251 | D31: 830428 | E31: =L31+N31 -> 512.03932 | F31: =$C$4*K31 -> 25000 | G31: =D31-F31 -> 805428 | H31: Landis Report | I31: Missing | J31: =K31+M31 -> 21650.04 | K31: 1000 | L31: =K31/365*2*3 -> 16.438356 | M31: =C31/$C$5 -> 20650.04 | N31: =M31/$C$6*$C$7*$C$8 -> 495.60096 | O31: =E31-$E$21 -> 255.43132 | P31: =C31/M31 -> 25 | Q31: =D31/K31 -> 830.428
A32: 2002 | C32: 472945 | D32: 736289 | E32: =L32+N32 -> 470.46556 | F32: =$C$4*K32 -> 25000 | G32: =D32-F32 -> 711289 | H32: Landis Report | I32: Missing | J32: =K32+M32 -> 19917.8 | K32: 1000 | L32: =K32/365*2*3 -> 16.438356 | M32: =C32/$C$5 -> 18917.8 | N32: =M32/$C$6*$C$7*$C$8 -> 454.0272 | O32: =E32-$E$21 -> 213.85756 | P32: =C32/M32 -> 25 | Q32: =D32/K32 -> 736.289
A33: 2001 | B33: Article in Cement Review about Expansion Project and New Oxygen Tanks | C33: 508733 | D33: 760801 | E33: =L33+N33 -> 504.82204 | F33: =$C$4*K33 -> 25000 | G33: =D33-F33 -> 735801 | H33: Landis Report | I33: Missing | J33: =K33+M33 -> 21349.32 | K33: 1000 | L33: =K33/365*2*3 -> 16.438356 | M33: =C33/$C$5 -> 20349.32 | N33: =M33/$C$6*$C$7*$C$8 -> 488.38368 | O33: =E33-$E$21 -> 248.21404 | P33: =C33/M33 -> 25 | Q33: =D33/K33 -> 760.801
A34: 2000 | B34: $10M Plant Expansion Project Ongoing; CEMEX Acquires Facility from Southdown | C34: 541747 | D34: 846129 | E34: =L34+N34 -> 536.51548 | F34: =$C$4*K34 -> 25000 | G34: =D34-F34 -> 821129 | H34: Landis Report | I34: Missing | J34: =K34+M34 -> 22669.88 | K34: 1000 | L34: =K34/365*2*3 -> 16.438356 | M34: =C34/$C$5 -> 21669.88 | N34: =M34/$C$6*$C$7*$C$8 -> 520.07712 | O34: =E34-$E$21 -> 279.90748 | P34: =C34/M34 -> 25 | Q34: =D34/K34 -> 846.129
A35: 1999 | B35: $10M Plant Expansion Project Ongoing | C35: 500031 | D35: 845049 | E35: =L35+N35 -> 496.46812 | F35: =$C$4*K35 -> 25000 | G35: =D35-F35 -> 820049 | H35: Landis Report | I35: Missing | J35: =K35+M35 -> 21001.24 | K35: 1000 | L35: =K35/365*2*3 -> 16.438356 | M35: =C35/$C$5 -> 20001.24 | N35: =M35/$C$6*$C$7*$C$8 -> 480.02976 | O35: =E35-$E$21 -> 239.86012 | P35: =C35/M35 -> 25 | Q35: =D35/K35 -> 845.049
A36: 1998 | B36: $10M Plant Expansion Project Begins | C36: 503192 | D36: 826631 | E36: =L36+N36 -> 499.50268 | F36: =$C$4*K36 -> 25000 | G36: =D36-F36 -> 801631 | H36: Landis Report | I36: Missing | J36: =K36+M36 -> 21127.68 | K36: 1000 | L36: =K36/365*2*3 -> 16.438356 | M36: =C36/$C$5 -> 20127.68 | N36: =M36/$C$6*$C$7*$C$8 -> 483.06432 | O36: =E36-$E$21 -> 242.89468 | P36: =C36/M36 -> 25 | Q36: =D36/K36 -> 826.631
A37: 1997 | B37: Dowe Flats Starts Producing Material and Transports via Conveyor over Highway 66 | C37: 458694 | E37: =L37+N37 -> 456.7846 | F37: =$C$4*K37 -> 25000 | G37: 100000 | H37: Landis Report | I37: Missing | J37: =K37+M37 -> 19347.76 | K37: 1000 | L37: =K37/365*2*3 -> 16.438356 | M37: =C37/$C$5 -> 18347.76 | N37: =M37/$C$6*$C$7*$C$8 -> 440.34624 | O37: =E37-$E$21 -> 200.1766 | P37: =C37/M37 -> 25 | Q37: =D37/K37 -> 0
A38: 1996 | B38: Larimer Pits last shipment Jan 1997 | C38: 430272 | D38: 754404 | E38: =L38+N38 -> 429.49948 | F38: =$C$4*K38 -> 25000 | G38: =D38-F38 -> 729404 | H38: Landis Report | I38: Missing | J38: =K38+M38 -> 18210.88 | K38: 1000 | L38: =K38/365*2*3 -> 16.438356 | M38: =C38/$C$5 -> 17210.88 | N38: =M38/$C$6*$C$7*$C$8 -> 413.06112 | O38: =E38-$E$21 -> 172.89148 | P38: =C38/M38 -> 25 | Q38: =D38/K38 -> 754.404
A39: 1995 | C39: 425274 | D39: 735768 | E39: =L39+N39 -> 424.7014 | F39: =$C$4*K39 -> 25000 | G39: =D39-F39 -> 710768 | H39: Landis Report | I39: Missing | J39: =K39+M39 -> 18010.96 | K39: 1000 | L39: =K39/365*2*3 -> 16.438356 | M39: =C39/$C$5 -> 17010.96 | N39: =M39/$C$6*$C$7*$C$8 -> 408.26304 | O39: =E39-$E$21 -> 168.0934 | P39: =C39/M39 -> 25 | Q39: =D39/K39 -> 735.768
A40: 1994 | B40: CEMEX Lyons becomes a Nonconforming Use as Boulder County Land Use Code is Adopted - October 18th, 1994 | C40: 286048 | D40: 418505 | E40: =L40+N40 -> 329.07552 | F40: 56739 | G40: =D40-F40 -> 361766 | H40: Landis Report | I40: Missing | J40: =K40+M40 -> 13711.48 | K40: =F40/$C$4 -> 2269.56 | L40: =K40/$C$6*$C$7*$C$8 -> 54.46944 | M40: =C40/$C$4 -> 11441.92 | N40: =M40/$C$6*$C$7*$C$8 -> 274.60608 | O40: =E40-$E$21 -> 72.46752 | P40: =C40/M40 -> 25 | Q40: =D40/K40 -> 184.39918
A41: 1993 | B41: Lyons Quarry, Pit E, South of Hygiene Road, Ceases Operation - July 1993 Dowe Flats Application Begins | C41: 419230 | D41: =C41*$C$3+$D$3 -> 678840.06 | E41: =L41+N41 -> 578.76768 | F41: 183653 | G41: =D41-F41 -> 495187.06 | H41: Calculated - Landis Report | I41: 30716 | J41: =K41+M41 -> 24115.32 | K41: =F41/$C$4 -> 7346.12 | L41: =K41/$C$6*$C$7*$C$8 -> 176.30688 | M41: =C41/$C$4 -> 16769.2 | N41: =M41/$C$6*$C$7*$C$8 -> 402.4608 | O41: =E41-$E$21 -> 322.15968 | P41: =C41/M41 -> 25 | Q41: =D41/K41 -> 92.407973
...

Sheet Exhibit - ADT Summary
B2: Summary ADT Information | C2: ADTs (Inbound + Outbound) | D2: Raw Material ADTs (Inbound) | E2: Finished Product ADTs (Outbound)
B3: Average ADTs from 1983 to 1993 (Lyons Quarry Primary Source) | C3: =AVERAGE(Data!E41,Data!E42,Data!E44,Data!E45,Data!E47,Data!E48,Data!E49,Data!E50,Data!E51) -> 409.48846 | D3: =AVERAGE(Data!L41,Data!L42,Data!L44,Data!L45,Data!L47,Data!L48,Data!L49,Data!L50,Data!L51) -> 34.201525 | E3: =AVERAGE(Data!N41,Data!N42,Data!N44,Data!N45,Data!N47,Data!N48,Data!N49,Data!N50,Data!N51) -> 375.28693
B4: ADTs in 1994 @ time of Nonconforming Use | C4: =Data!E40 -> 329.07552 | D4: =Data!L40 -> 54.46944 | E4: =Data!N40 -> 274.60608
B5: Average ADTs from 1994 to 2018 (Since Nonconforming Use - 25 years) | C5: =AVERAGE(Data!E16:E40) -> 384.85322 | D5: =AVERAGE(Data!L16:L40) -> 22.286214 | E5: =AVERAGE(Data!N16:N40) -> 362.567
B6: Average ADTs from 2009 to 2018 (10 years) | C6: =AVERAGE('Exhibit - Total ADTs'!M8:M17) -> 260.73011 | D6: =AVERAGE('Exhibit - Total ADTs'!H8:H17) -> 21.192472 | E6: =AVERAGE('Exhibit - Total ADTs'!K8:K18) -> 245.29716
B7: Average ADTs from 2019 to 2022 (Trucking from Wyoming) | C7: =AVERAGE(Data!E11:E14) -> 640.76627 | D7: =MEDIAN(Data!L11:L14) -> 273.648 | E7: =MEDIAN(Data!N11:N14) -> 345.3
B8: Average ADTs in 2023 (through April) | C8: =SUM(D8:E8) -> 594.66667 | D8: ='Exhibit - Total ADTs'!H22 -> 302.96296 | E8: ='Exhibit - Total ADTs'!K22 -> 291.7037
B9: Average ADTs from Oct to April 2023 (Since Dowe Flats Closure) | C9: =SUM(D9:E9) -> 626.44898 | D9: ='Exhibit - Post Dowe Flats ADTs'!H15 -> 320.85714 | E9: ='Exhibit - Post Dowe Flats ADTs'!J15 -> 305.59184
B11: Average Increase (Decrease) in 2023 ADTs vs 1983-1993 | C11: =C8-C3 -> 185.17821 | D11: =D8-D3 -> 268.76144 | E11: =E8-E3 -> -83.58323
B12: Average Increase (Decrease) in 2023 ADTs vs 1994 | C12: =C8-C4 -> 265.59115 | D12: =D8-D4 -> 248.49352 | E12: =E8-E4 -> 17.097624
B13: Average Increase (Decrease) in 2023 ADTs vs 1994-2018 | C13: =C8-C5 -> 209.81345 | D13: =D8-D5 -> 280.67675 | E13: =E8-E5 -> -70.863298
B14: Average Increase (Decrease) in 2023 ADTs vs 2009-2018 | C14: =C8-C6 -> 333.93656 | D14: =D8-D6 -> 281.77049 | E14: =E8-E6 -> 46.406541
B16: Average Increase (Decrease) in Post Dowe Flats ADTs vs 1983-1993 | C16: =C9-C3 -> 216.96052 | D16: =D9-D3 -> 286.65562 | E16: =E9-E3 -> -69.695097
B17: Average Increase (Decrease) in Post Dowe Flats ADTs vs 1994 | C17: =C9-C4 -> 297.37346 | D17: =D9-D4 -> 266.3877 | E17: =E9-E4 -> 30.985757
B18: Average Increase (Decrease) in Post Dowe Flats ADTs vs 1994-2018 | C18: =C9-C5 -> 241.59576 | D18: =D9-D5 -> 298.57093 | E18: =E9-E5 -> -56.975165
B19: Average Increase (Decrease) in Post Dowe Flats ADTs vs 2009-2018 | C19: =C9-C6 -> 365.71887 | D19: =D9-D6 -> 299.66467 | E19: =E9-E6 -> 60.294674

Sheet Exhibit - Corrected Landis Repo
B1: EXHIBIT [X] - Landis Appendix B with Correct Arithmetic Applied
C4: Year | D4: Truck Volumes | E4: Workdays Per Year | F4: Average Daily Traffic | G4: As Reported ADTs (Passenger Car Equivalent) | H4: Corrected Average Daily Traffic Calculations | I4: Corrected ADTs (Passenger Car Equivalent) | J4: CEMEX Overstatement / (Understatement) of ADTs
B6: Truck Volume Numbers from CEMEX | C6: 2014 | D6: 9602 | E6: 250 | F6: 96 | G6: =Data!$C$7*Data!$C$8*F6 -> 576 | H6: =D6/E6 -> 38.408 | I6: =H6*Data!$C$7*Data!$C$8 -> 230.448 | J6: =G6-I6 -> 345.552
C7: 2015 | D7: 8729 | E7: 250 | F7: 53 | G7: =Data!$C$7*Data!$C$8*F7 -> 318 | H7: =D7/E7 -> 34.916 | I7: =H7*Data!$C$7*Data!$C$8 -> 209.496 | J7: =G7-I7 -> 108.504
C8: 2016 | D8: 11305 | E8: 252 | F8: 63 | G8: =Data!$C$7*Data!$C$8*F8 -> 378 | H8: =D8/E8 -> 44.861111 | I8: =H8*Data!$C$7*Data!$C$8 -> 269.16667 | J8: =G8-I8 -> 108.83333
C9: 2017 | D9: 14330 | E9: 251 | F9: 93 | G9: =Data!$C$7*Data!$C$8*F9 -> 558 | H9: =D9/E9 -> 57.091633 | I9: =H9*Data!$C$7*Data!$C$8 -> 342.5498 | J9: =G9-I9 -> 215.4502
C10: 2018 | D10: 14557 | E10: 251 | F10: 75 | G10: =Data!$C$7*Data!$C$8*F10 -> 450 | H10: =D10/E10 -> 57.996016 | I10: =H10*Data!$C$7*Data!$C$8 -> 347.9761 | J10: =G10-I10 -> 102.0239
C11: 2019 | D11: 19478 | E11: 251 | F11: 64 | G11: =Data!$C$7*Data!$C$8*F11 -> 384 | H11: =D11/E11 -> 77.601594 | I11: =H11*Data!$C$7*Data!$C$8 -> 465.60956 | J11: =G11-I11 -> -81.609562
C12: 2020 | D12: 28481 | E12: 250 | F12: 98 | G12: =Data!$C$7*Data!$C$8*F12 -> 588 | H12: =D12/E12 -> 113.924 | I12: =H12*Data!$C$7*Data!$C$8 -> 683.544 | J12: =G12-I12 -> -95.544
C13: 2021 | D13: 23277 | E13: 251 | F13: 79 | G13: =Data!$C$7*Data!$C$8*F13 -> 474 | H13: =D13/E13 -> 92.737052 | I13: =H13*Data!$C$7*Data!$C$8 -> 556.42231 | J13: =G13-I13 -> -82.422311
C14: 2022 | D14: 24660 | E14: 251 | F14: 82 | G14: =Data!$C$7*Data!$C$8*F14 -> 492 | H14: =D14/E14 -> 98.247012 | I14: =H14*Data!$C$7*Data!$C$8 -> 589.48207 | J14: =G14-I14 -> -97.482072
B15: Calculated with Regression Equation | C15: 2023 | D15: 20106 | E15: 251 | F15: 67 | G15: =Data!$C$7*Data!$C$8*F15 -> 402 | H15: =D15/E15 -> 80.103586 | I15: =H15*Data!$C$7*Data!$C$8 -> 480.62151 | J15: =G15-I15 -> -78.621514

Sheet Exhibit - Inbound ADTs
B1: EXHIBIT [X] - CEMEX - As Repoted Inbound Raw Material ADTs
C4: Year | D4: Inbound Truck Volumes | E4: Workdays Per Year | F4: Average Daily Truck Volume | G4: ADTs (Passenger Car Equivalent) | H4: Median ADTs from 2009-2023
B5: Truck Volume Numbers from CEMEX | C5: 2006 | D5: =Data!K28 -> 955 | E5: 252 | F5: =D5/E5 -> 3.7896825 | G5: =F5*Data!$C$7*Data!$C$8 -> 22.738095 | H5: =MEDIAN($G$5:$G$22) -> 23.058291
C6: 2007 | D6: =Data!K27 -> 950 | E6: 251 | F6: =D6/E6 -> 3.7848606 | G6: =F6*Data!$C$7*Data!$C$8 -> 22.709163 | H6: =MEDIAN($G$5:$G$22) -> 23.058291
C7: 2008 | D7: =Data!K26 -> 1035 | E7: 251 | F7: =D7/E7 -> 4.123506 | G7: =F7*Data!$C$7*Data!$C$8 -> 24.741036 | H7: =MEDIAN($G$5:$G$22) -> 23.058291
C8: 2009 | D8: =Data!K25 -> 392 | E8: 251 | F8: =D8/E8 -> 1.561753 | G8: =F8*Data!$C$7*Data!$C$8 -> 9.3705179 | H8: =MEDIAN($G$8:$G$22) -> 23.378486
C9: 2010 | D9: =Data!K24 -> 734 | E9: 250 | F9: =D9/E9 -> 2.936 | G9: =F9*Data!$C$7*Data!$C$8 -> 17.616 | H9: =MEDIAN($G$8:$G$22) -> 23.378486
C10: 2011 | D10: =Data!K23 -> 978 | E10: 251 | F10: =D10/E10 -> 3.8964143 | G10: =F10*Data!$C$7*Data!$C$8 -> 23.378486 | H10: =MEDIAN($G$8:$G$22) -> 23.378486
C11: 2012 | D11: =Data!K22 -> 2234 | E11: 251 | F11: =D11/E11 -> 8.9003984 | G11: =F11*Data!$C$7*Data!$C$8 -> 53.40239 | H11: =MEDIAN($G$8:$G$22) -> 23.378486
C12: 2013 | D12: =Data!K19 -> 639 | E12: 251 | F12: =D12/E12 -> 2.5458167 | G12: =F12*Data!$C$7*Data!$C$8 -> 15.2749 | H12: =MEDIAN($G$8:$G$22) -> 23.378486
C13: 2014 | D13: =Data!K18 -> 798 | E13: 250 | F13: =D13/E13 -> 3.192 | G13: =F13*Data!$C$7*Data!$C$8 -> 19.152 | H13: =MEDIAN($G$8:$G$22) -> 23.378486
C14: 2015 | D14: =Data!K19 -> 639 | E14: 250 | F14: =D14/E14 -> 2.556 | G14: =F14*Data!$C$7*Data!$C$8 -> 15.336 | H14: =MEDIAN($G$8:$G$22) -> 23.378486
C15: 2016 | D15: =Data!K18 -> 798 | E15: 252 | F15: =D15/E15 -> 3.1666667 | G15: =F15*Data!$C$7*Data!$C$8 -> 19 | H15: =MEDIAN($G$8:$G$22) -> 23.378486
C16: 2017 | D16: =Data!K17 -> 607 | E16: 251 | F16: =D16/E16 -> 2.4183267 | G16: =F16*Data!$C$7*Data!$C$8 -> 14.50996 | H16: =MEDIAN($G$8:$G$22) -> 23.378486
C17: 2018 | D17: =Data!K16 -> 1041 | E17: 251 | F17: =D17/E17 -> 4.1474104 | G17: =F17*Data!$C$7*Data!$C$8 -> 24.884462 | H17: =MEDIAN($G$8:$G$22) -> 23.378486
C18: 2019 | D18: =Data!K15 -> 6807 | E18: 251 | F18: =D18/E18 -> 27.119522 | G18: =F18*Data!$C$7*Data!$C$8 -> 162.71713 | H18: =MEDIAN($G$8:$G$22) -> 23.378486
C19: 2020 | D19: =Data!K14 -> 12966 | E19: 250 | F19: =D19/E19 -> 51.864 | G19: =F19*Data!$C$7*Data!$C$8 -> 311.184 | H19: =MEDIAN($G$8:$G$22) -> 23.378486
C20: 2021 | D20: =Data!K13 -> 9838 | E20: 251 | F20: =D20/E20 -> 39.195219 | G20: =F20*Data!$C$7*Data!$C$8 -> 235.17131 | H20: =MEDIAN($G$8:$G$22) -> 23.378486
C21: 2022 | D21: =Data!K12 -> 9324 | E21: 251 | F21: =D21/E21 -> 37.14741 | G21: =F21*Data!$C$7*Data!$C$8 -> 222.88446 | H21: =MEDIAN($G$8:$G$22) -> 23.378486
C22: 2023 (through April) | D22: =946+1105+1036+1003 -> 4090 | E22: 81 | F22: =D22/E22 -> 50.493827 | G22: =F22*Data!$C$7*Data!$C$8 -> 302.96296 | H22: =MEDIAN($G$8:$G$22) -> 23.378486

Sheet Exhibit - Total ADTs
B1: EXHIBIT [X] - CEMEX - As Reported Total ADTs
C4: Year | D4: Inbound Truck Volumes | E4: Outbound Truck Volumes | F4: Workdays Per Year | G4: Average Inbound Daily Truck Volume | H4: Inbound ADTs (Passenger Car Equivalent) | I4: Median Inbound ADTs from 2006-2023 | J4: Average Outbound Daily Truck Volume | K4: Outbound ADTs (Passenger Car Equivalent) | L4: Median Outbound ADTs from 2006-2023 | M4: Total ADTs | N4: Median ADTs from 2009 to 2023)
B5: Truck Volume Numbers from CEMEX | C5: 2006 | D5: =Data!K28 -> 955 | E5: =Data!M28 -> 18476 | F5: 252 | G5: =D5/F5 -> 3.7896825 | H5: =G5*Data!$C$7*Data!$C$8 -> 22.738095 | I5: =MEDIAN($H$5:$H$22) -> 23.058291 | J5: =E5/F5 -> 73.31746 | K5: =J5*Data!$C$7*Data!$C$8 -> 439.90476 | L5: =MEDIAN($K$5:$K$22) -> 297.29807 | M5: =H5+K5 -> 462.64286 | N5: =MEDIAN($M$8:$M$22) -> 269.21116
C6: 2007 | D6: =Data!K27 -> 950 | E6: =Data!M27 -> 20058 | F6: 251 | G6: =D6/F6 -> 3.7848606 | H6: =G6*Data!$C$7*Data!$C$8 -> 22.709163 | I6: =MEDIAN($H$5:$H$22) -> 23.058291 | J6: =E6/F6 -> 79.912351 | K6: =J6*Data!$C$7*Data!$C$8 -> 479.4741 | L6: =MEDIAN($K$5:$K$22) -> 297.29807 | M6: =H6+K6 -> 502.18327 | N6: =MEDIAN($M$8:$M$22) -> 269.21116
C7: 2008 | D7: =Data!K26 -> 1035 | E7: =Data!M26 -> 16770 | F7: 251 | G7: =D7/F7 -> 4.123506 | H7: =G7*Data!$C$7*Data!$C$8 -> 24.741036 | I7: =MEDIAN($H$5:$H$22) -> 23.058291 | J7: =E7/F7 -> 66.812749 | K7: =J7*Data!$C$7*Data!$C$8 -> 400.87649 | L7: =MEDIAN($K$5:$K$22) -> 297.29807 | M7: =H7+K7 -> 425.61753 | N7: =MEDIAN($M$8:$M$22) -> 269.21116
C8: 2009 | D8: =Data!K25 -> 392 | E8: =Data!M25 -> 9407 | F8: 251 | G8: =D8/F8 -> 1.561753 | H8: =G8*Data!$C$7*Data!$C$8 -> 9.3705179 | I8: =MEDIAN($H$5:$H$22) -> 23.058291 | J8: =E8/F8 -> 37.478088 | K8: =J8*Data!$C$7*Data!$C$8 -> 224.86853 | L8: =MEDIAN($K$5:$K$22) -> 297.29807 | M8: =H8+K8 -> 234.23904 | N8: =MEDIAN($M$8:$M$22) -> 269.21116
C9: 2010 | D9: =Data!K24 -> 734 | E9: =Data!M24 -> 9290 | F9: 250 | G9: =D9/F9 -> 2.936 | H9: =G9*Data!$C$7*Data!$C$8 -> 17.616 | I9: =MEDIAN($H$5:$H$22) -> 23.058291 | J9: =E9/F9 -> 37.16 | K9: =J9*Data!$C$7*Data!$C$8 -> 222.96 | L9: =MEDIAN($K$5:$K$22) -> 297.29807 | M9: =H9+K9 -> 240.576 | N9: =MEDIAN($M$8:$M$22) -> 269.21116
C10: 2011 | D10: =Data!K23 -> 978 | E10: =Data!M23 -> 9338 | F10: 251 | G10: =D10/F10 -> 3.8964143 | H10: =G10*Data!$C$7*Data!$C$8 -> 23.378486 | I10: =MEDIAN($H$5:$H$22) -> 23.058291 | J10: =E10/F10 -> 37.203187 | K10: =J10*Data!$C$7*Data!$C$8 -> 223.21912 | L10: =MEDIAN($K$5:$K$22) -> 297.29807 | M10: =H10+K10 -> 246.59761 | N10: =MEDIAN($M$8:$M$22) -> 269.21116
C11: 2012 | D11: =Data!K22 -> 2234 | E11: =Data!M22 -> 9028 | F11: 251 | G11: =D11/F11 -> 8.9003984 | H11: =G11*Data!$C$7*Data!$C$8 -> 53.40239 | I11: =MEDIAN($H$5:$H$22) -> 23.058291 | J11: =E11/F11 -> 35.968127 | K11: =J11*Data!$C$7*Data!$C$8 -> 215.80876 | L11: =MEDIAN($K$5:$K$22) -> 297.29807 | M11: =H11+K11 -> 269.21116 | N11: =MEDIAN($M$8:$M$22) -> 269.21116
C12: 2013 | D12: =Data!K19 -> 639 | E12: =Data!M21 -> 8808 | F12: 251 | G12: =D12/F12 -> 2.5458167 | H12: =G12*Data!$C$7*Data!$C$8 -> 15.2749 | I12: =MEDIAN($H$5:$H$22) -> 23.058291 | J12: =E12/F12 -> 35.091633 | K12: =J12*Data!$C$7*Data!$C$8 -> 210.5498 | L12: =MEDIAN($K$5:$K$22) -> 297.29807 | M12: =H12+K12 -> 225.8247 | N12: =MEDIAN($M$8:$M$22) -> 269.21116
C13: 2014 | D13: =Data!K18 -> 798 | E13: =Data!M20 -> 8438 | F13: 250 | G13: =D13/F13 -> 3.192 | H13: =G13*Data!$C$7*Data!$C$8 -> 19.152 | I13: =MEDIAN($H$5:$H$22) -> 23.058291 | J13: =E13/F13 -> 33.752 | K13: =J13*Data!$C$7*Data!$C$8 -> 202.512 | L13: =MEDIAN($K$5:$K$22) -> 297.29807 | M13: =H13+K13 -> 221.664 | N13: =MEDIAN($M$8:$M$22) -> 269.21116
C14: 2015 | D14: =Data!K19 -> 639 | E14: =Data!M19 -> 8090 | F14: 250 | G14: =D14/F14 -> 2.556 | H14: =G14*Data!$C$7*Data!$C$8 -> 15.336 | I14: =MEDIAN($H$5:$H$22) -> 23.058291 | J14: =E14/F14 -> 32.36 | K14: =J14*Data!$C$7*Data!$C$8 -> 194.16 | L14: =MEDIAN($K$5:$K$22) -> 297.29807 | M14: =H14+K14 -> 209.496 | N14: =MEDIAN($M$8:$M$22) -> 269.21116
C15: 2016 | D15: =Data!K18 -> 798 | E15: =Data!M18 -> 10507 | F15: 252 | G15: =D15/F15 -> 3.1666667 | H15: =G15*Data!$C$7*Data!$C$8 -> 19 | I15: =MEDIAN($H$5:$H$22) -> 23.058291 | J15: =E15/F15 -> 41.694444 | K15: =J15*Data!$C$7*Data!$C$8 -> 250.16667 | L15: =MEDIAN($K$5:$K$22) -> 297.29807 | M15: =H15+K15 -> 269.16667 | N15: =MEDIAN($M$8:$M$22) -> 269.21116
C16: 2017 | D16: =Data!K17 -> 607 | E16: =Data!M17 -> 13723 | F16: 251 | G16: =D16/F16 -> 2.4183267 | H16: =G16*Data!$C$7*Data!$C$8 -> 14.50996 | I16: =MEDIAN($H$5:$H$22) -> 23.058291 | J16: =E16/F16 -> 54.673307 | K16: =J16*Data!$C$7*Data!$C$8 -> 328.03984 | L16: =MEDIAN($K$5:$K$22) -> 297.29807 | M16: =H16+K16 -> 342.5498 | N16: =MEDIAN($M$8:$M$22) -> 269.21116
C17: 2018 | D17: =Data!K16 -> 1041 | E17: =Data!M16 -> 13516 | F17: 251 | G17: =D17/F17 -> 4.1474104 | H17: =G17*Data!$C$7*Data!$C$8 -> 24.884462 | I17: =MEDIAN($H$5:$H$22) -> 23.058291 | J17: =E17/F17 -> 53.848606 | K17: =J17*Data!$C$7*Data!$C$8 -> 323.09163 | L17: =MEDIAN($K$5:$K$22) -> 297.29807 | M17: =H17+K17 -> 347.9761 | N17: =MEDIAN($M$8:$M$22) -> 269.21116
C18: 2019 | D18: =Data!K15 -> 6807 | E18: =Data!M15 -> 12671 | F18: 251 | G18: =D18/F18 -> 27.119522 | H18: =G18*Data!$C$7*Data!$C$8 -> 162.71713 | I18: =MEDIAN($H$5:$H$22) -> 23.058291 | J18: =E18/F18 -> 50.482072 | K18: =J18*Data!$C$7*Data!$C$8 -> 302.89243 | L18: =MEDIAN($K$5:$K$22) -> 297.29807 | M18: =H18+K18 -> 465.60956 | N18: =MEDIAN($M$8:$M$22) -> 269.21116
C19: 2020 | D19: =Data!K14 -> 12966 | E19: =Data!M14 -> 15515 | F19: 250 | G19: =D19/F19 -> 51.864 | H19: =G19*Data!$C$7*Data!$C$8 -> 311.184 | I19: =MEDIAN($H$5:$H$22) -> 23.058291 | J19: =E19/F19 -> 62.06 | K19: =J19*Data!$C$7*Data!$C$8 -> 372.36 | L19: =MEDIAN($K$5:$K$22) -> 297.29807 | M19: =H19+K19 -> 683.544 | N19: =MEDIAN($M$8:$M$22) -> 269.21116
C20: 2021 | D20: =Data!K13 -> 9838 | E20: =Data!M13 -> 13439 | F20: 251 | G20: =D20/F20 -> 39.195219 | H20: =G20*Data!$C$7*Data!$C$8 -> 235.17131 | I20: =MEDIAN($H$5:$H$22) -> 23.058291 | J20: =E20/F20 -> 53.541833 | K20: =J20*Data!$C$7*Data!$C$8 -> 321.251 | L20: =MEDIAN($K$5:$K$22) -> 297.29807 | M20: =H20+K20 -> 556.42231 | N20: =MEDIAN($M$8:$M$22) -> 269.21116
C21: 2022 | D21: =Data!K12 -> 9324 | E21: =Data!M12 -> 15336 | F21: 251 | G21: =D21/F21 -> 37.14741 | H21: =G21*Data!$C$7*Data!$C$8 -> 222.88446 | I21: =MEDIAN($H$5:$H$22) -> 23.058291 | J21: =E21/F21 -> 61.099602 | K21: =J21*Data!$C$7*Data!$C$8 -> 366.59761 | L21: =MEDIAN($K$5:$K$22) -> 297.29807 | M21: =H21+K21 -> 589.48207 | N21: =MEDIAN($M$8:$M$22) -> 269.21116
C22: 2023 (through April) | D22: =946+1105+1036+1003 -> 4090 | E22: =702+900+1053+1283 -> 3938 | F22: 81 | G22: =D22/F22 -> 50.493827 | H22: =G22*Data!$C$7*Data!$C$8 -> 302.96296 | I22: =MEDIAN($H$5:$H$22) -> 23.058291 | J22: =E22/F22 -> 48.617284 | K22: =J22*Data!$C$7*Data!$C$8 -> 291.7037 | L22: =MEDIAN($K$5:$K$22) -> 297.29807 | M22: =H22+K22 -> 594.66667 | N22: =MEDIAN($M$8:$M$22) -> 269.21116

Sheet Exhibit - Feed to Clinker
B2: Year | C2: Feed Tons Per Year | D2: Clinker Tons Per Year | G2: Year | H2: Feed Tons Per Year | I2: Clinker Tons Per Year | J2: Calculated Truck Volumes | K2: Calculated Total ADTs
A3: As Reported by CEMEX from CDPHE Inspection Reports | B3: 2006 | C3: 734456 | D3: 466173 | F3: As Reported by CEMEX from CDPHE Inspection Reports | G3: 2006 | H3: 734456 | I3: 466173
B4: 2005 | C4: 739260 | D4: 440384 | G4: 2005 | H4: 739260 | I4: 440384
B5: =B4-1 -> 2004 | C5: 791866 | D5: 472053 | G5: =G4-1 -> 2004 | H5: 791866 | I5: 472053
B6: =B5-1 -> 2003 | C6: 830428 | D6: 512251 | G6: =G5-1 -> 2003 | H6: 830428 | I6: 512251
B7: =B6-1 -> 2002 | C7: 736289 | D7: 472945 | G7: =G6-1 -> 2002 | H7: 736289 | I7: 472945
B8: =B7-1 -> 2001 | C8: 760801 | D8: 494460 | G8: =G7-1 -> 2001 | H8: 760801 | I8: 494460
B9: =B8-1 -> 2000 | C9: 846129 | D9: 539992 | G9: =G8-1 -> 2000 | H9: 846129 | I9: 539992
B10: =B9-1 -> 1999 | C10: 845049 | D10: 500031 | G10: =G9-1 -> 1999 | H10: 845049 | I10: 500031
B11: =B10-1 -> 1998 | C11: 826631 | D11: 503192 | G11: =G10-1 -> 1998 | H11: 826631 | I11: 503192
B12: 1996 | C12: 754404 | D12: 430272 | G12: 1996 | H12: 754404 | I12: 430272
B13: 1989 | C13: 624874 | D13: 385921 | F13: Calculated By Regression Equation | G13: 1994 | H13: 419229 | I13: =0.518*H13+68887 -> 286047.62 | J13: =0.0815*I13-3433 -> 19879.881 | K13: =J13/250*6 -> 477.11715
B14: 1987 | C14: 493292 | D14: 352161 | G14: 1993 | H14: 416229 | I14: =0.518*H14+68887 -> 284493.62 | J14: =0.0815*I14-3433 -> 19753.23 | K14: =J14/250*6 -> 474.07752
B15: 1986 | C15: 624573 | D15: 375197 | F15: As Reported by CEMEX from CDPHE Inspection Reports | G15: 1989 | H15: 624874 | I15: 385921
B16: 1985 | C16: 784705 | D16: 444804 | G16: 1987 | H16: 493292 | I16: 352161
B17: 1984 | C17: 712760 | D17: 393478 | G17: 1986 | H17: 624573 | I17: 375197
G18: 1985 | H18: 784705 | I18: 444804
G19: 1984 | H19: 712760 | I19: 393478
A22: Landis Clinker Production and Annual Volumes
A23: Year | B23: Clinker Production (tons) | C23: Truck Volume
A24: 2019 | B24: 279546 | C24: 19478
A25: 2020 | B25: 388572 | C25: 28481
A26: 2021 | B26: 341316 | C26: 23277
A27: 2022 | B27: 336085 | C27: 24660

Sheet Exhibit - Post Dowe Flats ADTs
B1: EXHIBIT [X] - CEMEX - As Repoted Inbound Raw Material ADTs
C4: Year | D4: Inbound Truck Volumes | E4: Outbound Truck Volumes | F4: Workdays Per Month | G4: Average Inbound Daily Truck Volume | H4: Inbound ADTs (Passenger Car Equivalent) | I4: Average Outbound Daily Truck Volume | J4: Outbound ADTs (Passenger Car Equivalent) | K4: Total ADTs
B5: Truck Volume Numbers from CEMEX after the closure of Dowe Flats | C5: 2006 | D5: =Data!K28 -> 955 | F5: 252 | G5: =D5/F5 -> 3.7896825 | H5: =G5*Data!$C$7*Data!$C$8 -> 22.738095 | I5: =F5/H5 -> 11.082723 | J5: =I5*Data!$C$7*Data!$C$8 -> 66.496335
C6: 2007 | D6: =Data!K27 -> 950 | F6: 251 | G6: =D6/F6 -> 3.7848606 | H6: =G6*Data!$C$7*Data!$C$8 -> 22.709163 | I6: =F6/H6 -> 11.052807 | J6: =I6*Data!$C$7*Data!$C$8 -> 66.316842
C7: 2008 | D7: =Data!K26 -> 1035 | F7: 251 | G7: =D7/F7 -> 4.123506 | H7: =G7*Data!$C$7*Data!$C$8 -> 24.741036 | I7: =F7/H7 -> 10.145089 | J7: =I7*Data!$C$7*Data!$C$8 -> 60.870531
C8: 44835 | D8: 1345 | E8: 1626 | F8: 21 | G8: =D8/F8 -> 64.047619 | H8: =G8*Data!$C$7*Data!$C$8 -> 384.28571 | I8: =E8/F8 -> 77.428571 | J8: =I8*Data!$C$7*Data!$C$8 -> 464.57143 | K8: =J8+H8 -> 848.85714
C9: 44866 | D9: 1346 | E9: 1009 | F9: 21 | G9: =D9/F9 -> 64.095238 | H9: =G9*Data!$C$7*Data!$C$8 -> 384.57143 | I9: =E9/F9 -> 48.047619 | J9: =I9*Data!$C$7*Data!$C$8 -> 288.28571 | K9: =J9+H9 -> 672.85714
C10: 44896 | D10: 1080 | E10: 914 | F10: 21 | G10: =D10/F10 -> 51.428571 | H10: =G10*Data!$C$7*Data!$C$8 -> 308.57143 | I10: =E10/F10 -> 43.52381 | J10: =I10*Data!$C$7*Data!$C$8 -> 261.14286 | K10: =J10+H10 -> 569.71429
C11: 44927 | D11: 946 | E11: 702 | F11: 21 | G11: =D11/F11 -> 45.047619 | H11: =G11*Data!$C$7*Data!$C$8 -> 270.28571 | I11: =E11/F11 -> 33.428571 | J11: =I11*Data!$C$7*Data!$C$8 -> 200.57143 | K11: =J11+H11 -> 470.85714
C12: 44958 | D12: 1105 | E12: 900 | F12: 21 | G12: =D12/F12 -> 52.619048 | H12: =G12*Data!$C$7*Data!$C$8 -> 315.71429 | I12: =E12/F12 -> 42.857143 | J12: =I12*Data!$C$7*Data!$C$8 -> 257.14286 | K12: =J12+H12 -> 572.85714
C13: 44986 | D13: 1036 | E13: 1053 | F13: 21 | G13: =D13/F13 -> 49.333333 | H13: =G13*Data!$C$7*Data!$C$8 -> 296 | I13: =E13/F13 -> 50.142857 | J13: =I13*Data!$C$7*Data!$C$8 -> 300.85714 | K13: =J13+H13 -> 596.85714
C14: 45017 | D14: 1003 | E14: 1283 | F14: 21 | G14: =D14/F14 -> 47.761905 | H14: =G14*Data!$C$7*Data!$C$8 -> 286.57143 | I14: =E14/F14 -> 61.095238 | J14: =I14*Data!$C$7*Data!$C$8 -> 366.57143 | K14: =J14+H14 -> 653.14286
C15: Averages | D15: =AVERAGE(D8:D14) -> 1123 | E15: =AVERAGE(E8:E14) -> 1069.5714 | F15: =AVERAGE(F8:F14) -> 21 | G15: =AVERAGE(G8:G14) -> 53.47619 | H15: =AVERAGE(H8:H14) -> 320.85714 | I15: =AVERAGE(I8:I14) -> 50.931973 | J15: =AVERAGE(J8:J14) -> 305.59184 | K15: =AVERAGE(K8:K14) -> 626.44898

Sheet Landis Flaws
C2: Instructions: Please log errors & Flaws with the Landis Report. No matter how big or small, it all is relevant.
B4: Identified By | C4: Flaw Description
B5: Scott Wolf | C5: Appendix B (pg 28 in Landis Report) - the math is wrong. For example, in 2023: 20,106 truck trips divided by 251 working days is 80, not 67. Every row is calculated incorrectly.
B6: Scott Wolf | C6: Figure 8: Inappropriately mixing the units on the graph and misleading at best. CDOT traffic is truck trips (blue dots) whereas the daily trucks (orange trips) are roundtrips and thus understated, and should be scaled by at least 2X
B7: Scott Wolf | C7: Appendix C: 1) Route 066B marker 28.693 to marker 32.585 is HWY66 & HWY36 station. Seems like the wrong one for trucks coming from Wyoming. 2) ADDTRUCKS is all trucks. This includes 2 axel trucks (such as RVs and pickup trucks with dual rear wheels, but not "normal" pickups), as well as tractor+trailer "trucks". It is not strictly the count of a 3+ axel tractor+side dump that Cemex uses, which is reported separately.
B8: Scott Wolf | C8: CDOT Traffic data from OTIS used in the report is not a good indicator of Cemex traffic. Per correspondence with CDOT, "Short duraction" stations (which the station Landis used) is typically collected over a few days every 3 years. It is located "somewhere" along the segment. As such, this may not be reflecting traffic from Wyo (and given the graphic, probably not). For all of the attacks used by Landis against the Stantec report, the same and more can be said of the OTIS data.
B9: Scott Wolf | C9: Graphed data points from "Figure 3 Ten Year Comparative Daily Truck Volumes, Pre 1994 and Pre 2024" previous to 1995 do not match "Figure 8 Daily Truck Volumes on Ute Hwy/SH 66" and associated data table "APPENDIX B - ANNUAL AND DAILY CEMEX TRUCK VOLUMES". Other ranges may be incorrect. For example 1990 data point on Figure 3 is approximate 100. On figure 8 it is well under 100, and appendix B has the value as 87. (It should be 100... as 25191 / 251 == 100, not 87).
B10: Judy Koslov | C10: A rule of regression modeling is not to estimate outside the range of the data. Note that the clinker production in the years 1983, 1984, 1985, 1992 and 1993, which was used to estimate Annual Truck Volume for those years, exceeded the largest data value in the model. Given the gap of more than twenty years between the years in the regression model and the years whose truck volume was estimated, not to mention the upgrade to the kiln, how believable are the calculated values of Table 2?
B11: Judy Koslov | C11: Since the report is dated 11/5/2024, real 2023 truck counts (and half year 2024 truck counts too) should be used rather than a calculated value.
B12: Bart Lorang | C12: Boulder County's standard is ADTs - Average Daily Trips in PCEs (Passenger Car Equivalents) which is Boulder County and CDOT standard. A trip into the plant, and a trip out of the plant is 2 trips. A heavy truck is worth 3 Passenger Car Equivalents. So one roundtrip truck trip is worth 6 ADTs per Boulder County standards. Landis Report does not normalize its data to ADTs.
B13: Bart Lorang | C13: Plant became nonconforming October 18, 1994, but 1994 is completely omitted from the report.
B14: Bart Lorang | C14: Inappropriate to create a regresssion equation based solely on clinker; truck volume is based on clinker produced (a proxy for finished product shiipped) *and* raw materials trucked into the plant.
B15: Judy Koslov | C15: Question: Figure 2 on page 9 shows four datapoints that the authors claim are comparable to those from before 1994, since rail transport of finished product ended before 2019. These datapoints correspond to the years of the COVID epidemic, so are they representative of CEMEX’s continuing operation in 2023 and 2024?
... B27: Bart Lorang | C27: Report claims that Conveyor did not become operational in 1994. Conveyor became Operational in August, 1997

Sheet Data Dec18
A2: Key Assumptions | D2: Intercept Value | E2: Significance | F2: Legend - Sources | G2: Summary ADT Information | I2: Total ADTs | J2: Raw Material ADTs (Inbound) | K2: Finished Product ADTs (Outbound)
A3: Computing Raw Materials from Clinker Production | C3: 1.6009 | D3: 7694.7491 | E3: R^2 of 0.97 and p-value of 0.000 | F3: Landis Report - Reported | G3: ADTs in 1994 - Baseline @ Nonconforming Use | I3: =E40 -> 456.23424 | J3: =L40 -> 54.46944 | K3: =N40 -> 401.7648
A4: Historical Tons Per Inbound Truck (30 Ton Trucks) | C4: 25 | F4: Landis Report - Calculated | G4: Average ADTs from 1994 to 2018 - Since Nonconforming Use | I4: =AVERAGE(E16:E40) -> 389.8557 | J4: =AVERAGE(L16:L40) -> 22.286214 | K4: =AVERAGE(N16:N40) -> 367.56948
A5: Historical Tons Per Outbound Truck (30 Ton Truks) | C5: 25 | F5: CDPHE - Reported Data | G5: ADTs from 2019 to 2022 | I5: =AVERAGE(E11:E14) -> 640.76627 | J5: =AVERAGE(L11:L14) -> 305.66123 | K5: =AVERAGE(N11:N14) -> 335.10504
A6: Working Days Per Yeare for ADT (Average Daily Trips) | C6: 250 | F6: Unknown Data | G6: ADTs in 2023 | I6: =E11 -> 729.03309 | J6: =L11 -> 451.57293 | K6: =N11 -> 277.46016
A7: CDOT Multiplier Factor for Heavy Trucks to ADTs | C7: 3 | F7: Good Neighbors - Calculated | G7: Average Increase/Decrease in 2023 ADTs vs Baseline | I7: =I6-I3 -> 272.79885 | J7: =J6-J3 -> 397.10349 | K7: =K6-K3 -> -124.30464
A8: Roundtrip ADT Factor (Count Arrival & Departure) | C8: 2 | F8: Good Neighbors - Estimate
A10: Year | B10: Timeline of Key Events | C10: Clinker Production (tons) | D10: Raw Material Kiln Feed (tons) | E10: Total ADTs - Average Daily Trips (Calculated) | F10: Trucked In Raw Material (Larimer, Wyoming, Arcosa, Sandstone Mines) | G10: Conveyed or Hauled Raw Material (Dowe Flats or Lyons Quarry) | H10: Source | I10: Truck Volume (Inbound & Outbound) - Landis | J10: Total Trucks (Inbound & Outbound) - GNL | K10: Inbound Trucks (Raw Material) | L10: Inbound ADTs (Raw Material) | M10: Outbound Trucks (Finished Product) | N10: Outbound ADTs (Finished Product) | O10: ADT Change Compared to 1994 (When Noncomforing Use Came Into Effect) | P10: Clinker Tons Per Outbound Truck | Q10: Tons Raw Material Per Inbound Truck
A11: 2023 | B11: CEMEX fined $357K for Air Quality violations for April 2020 to May 2021 | C11: 289021 | D11: =C11*$C$3+$D$3 -> 470388.47 | E11: =L11+N11 -> 729.03309 | F11: =D11 -> 470388.47 | G11: =D11-F11 -> 0 | H11: Calculated - Landis Report | I11: 20106 | J11: =K11+M11 -> 30376.379 | K11: =D11/$C$4 -> 18815.539 | L11: =K11/$C$6*$C$7*$C$8 -> 451.57293 | M11: =C11/$C$5 -> 11560.84 | N11: =M11/$C$6*$C$7*$C$8 -> 277.46016 | O11: =E11-$E$21 -> 472.42509 | P11: =C11/M11 -> 25 | Q11: =D11/K11 -> 25
A12: 2022 | B12: Dowe Flat Closes - September 30th, 2022 | C12: 336085 | D12: =C12*$C$3+$D$3 -> 545733.23 | E12: =L12+N12 -> 591.84 | F12: =K12*$C$4 -> 233100 | G12: =D12-F12 -> 312633.23 | H12: Actuals - Landis Report | I12: 24660 | J12: =K12+M12 -> 24660 | K12: 9324 | L12: =K12/$C$6*$C$7*$C$8 -> 223.776 | M12: =I12-K12 -> 15336 | N12: =M12/$C$6*$C$7*$C$8 -> 368.064 | O12: =E12-$E$21 -> 335.232 | P12: =C12/M12 -> 21.914776 | Q12: =D12/K12 -> 58.529947
A13: 2021 | C13: 341316 | D13: =C13*$C$3+$D$3 -> 554107.53 | E13: =L13+N13 -> 558.648 | F13: =K13*$C$4 -> 245950 | G13: =D13-F13 -> 308157.53 | H13: Actuals - Landis Report | I13: 23277 | J13: =K13+M13 -> 23277 | K13: 9838 | L13: =K13/$C$6*$C$7*$C$8 -> 236.112 | M13: 13439 | N13: =M13/$C$6*$C$7*$C$8 -> 322.536 | O13: =E13-$E$21 -> 302.04 | P13: =C13/M13 -> 25.397425 | Q13: =D13/K13 -> 56.323189
A14: 2020 | C14: 388572 | D14: 605800 | E14: =L14+N14 -> 683.544 | F14: =K14*$C$4 -> 324150 | G14: =D14-F14 -> 281650 | H14: Actuals - Landis Report | I14: 28481 | J14: =K14+M14 -> 28481 | K14: 12966 | L14: =K14/$C$6*$C$7*$C$8 -> 311.184 | M14: =I14-K14 -> 15515 | N14: =M14/$C$6*$C$7*$C$8 -> 372.36 | O14: =E14-$E$21 -> 426.936 | P14: =C14/M14 -> 25.044924 | Q14: =D14/K14 -> 46.722197
A15: 2019 | C15: 279546 | D15: 517217 | E15: =L15+N15 -> 467.472 | F15: =K15*$C$4 -> 170175 | G15: =D15-F15 -> 347042 | H15: Actuals - Landis Report | I15: 19478 | J15: =K15+M15 -> 19478 | K15: 6807 | L15: =K15/$C$6*$C$7*$C$8 -> 163.368 | M15: 12671 | N15: =M15/$C$6*$C$7*$C$8 -> 304.104 | O15: =E15-$E$21 -> 210.864 | P15: =C15/M15 -> 22.061874 | Q15: =D15/K15 -> 75.983106
A16: 2018 | B16: CEMEX Acquires Weaver Mine in Wyoming - Sep 14, 2018 | C16: 313276 | D16: =C16*$C$3+$D$3 -> 509218.3 | E16: =L16+N16 -> 349.368 | F16: =K16*$C$4 -> 26025 | G16: =D16-F16 -> 483193.3 | H16: Actuals - Landis Report | I16: 14557 | J16: =K16+M16 -> 14557 | K16: 1041 | L16: =K16/$C$6*$C$7*$C$8 -> 24.984 | M16: 13516 | N16: =M16/$C$6*$C$7*$C$8 -> 324.384 | O16: =E16-$E$21 -> 92.76 | P16: =C16/M16 -> 23.178159 | Q16: =D16/K16 -> 489.16263
A17: 2017 | C17: 370385 | D17: 566401 | E17: =L17+N17 -> 343.92 | F17: =K17*$C$4 -> 15175 | G17: =D17-F17 -> 551226 | H17: Actuals - Landis Report | I17: 14330 | J17: =K17+M17 -> 14330 | K17: 607 | L17: =K17/$C$6*$C$7*$C$8 -> 14.568 | M17: =I17-K17 -> 13723 | N17: =M17/$C$6*$C$7*$C$8 -> 329.352 | O17: =E17-$E$21 -> 87.312 | P17: =C17/M17 -> 26.99009 | Q17: =D17/K17 -> 933.11532
A18: 2016 | C18: 275799 | D18: 512856 | E18: =L18+N18 -> 271.32 | F18: =K18*$C$4 -> 19950 | G18: =D18-F18 -> 492906 | H18: Actuals - Landis Report | I18: 11305 | J18: =K18+M18 -> 11305 | K18: 798 | L18: =K18/$C$6*$C$7*$C$8 -> 19.152 | M18: =I18-K18 -> 10507 | N18: =M18/$C$6*$C$7*$C$8 -> 252.168 | O18: =E18-$E$21 -> 14.712 | P18: =C18/M18 -> 26.249072 | Q18: =D18/K18 -> 642.67669
A19: 2015 | B19: CEMEX installs better polution equipment | C19: 244074 | D19: 424996 | E19: =L19+N19 -> 209.496 | F19: =K19*$C$4 -> 15975 | G19: =D19-F19 -> 409021 | H19: Actuals - Landis Report | I19: 8729 | J19: =K19+M19 -> 8729 | K19: 639 | L19: =K19/$C$6*$C$7*$C$8 -> 15.336 | M19: 8090 | N19: =M19/$C$6*$C$7*$C$8 -> 194.16 | O19: =E19-$E$21 -> -47.112 | P19: =C19/M19 -> 30.169839 | Q19: =D19/K19 -> 665.09546
A20: 2014 | C20: 381810 | D20: 441253 | E20: =L20+N20 -> 230.448 | F20: =K20*$C$4 -> 29100 | G20: =D20-F20 -> 412153 | H20: Actuals - Landis Report | I20: 9602 | J20: =K20+M20 -> 9602 | K20: 1164 | L20: =K20/$C$6*$C$7*$C$8 -> 27.936 | M20: =I20-K20 -> 8438 | N20: =M20/$C$6*$C$7*$C$8 -> 202.512 | O20: =E20-$E$21 -> -26.16 | P20: =C20/M20 -> 45.248874 | Q20: =D20/K20 -> 379.08333
A21: 2013 | B21: CEMEX settles with EPA for $1M & Agreement to Install Better Pollution Controls | C21: 341377 | D21: 552638 | E21: =L21+N21 -> 256.608 | F21: =K21*$C$4 -> 47100 | G21: =D21-F21 -> 505538 | H21: Actuals - Landis Report | I21: =K21+M21 -> 10692 | J21: =K21+M21 -> 10692 | K21: 1884 | L21: =K21/$C$6*$C$7*$C$8 -> 45.216 | M21: 8808 | N21: =M21/$C$6*$C$7*$C$8 -> 211.392 | O21: =E21-$E$21 -> 0 | P21: =C21/M21 -> 38.757607 | Q21: =D21/K21 -> 293.33227
A22: 2012 | E22: =L22+N22 -> 270.288 | F22: =K22*$C$4 -> 55850 | G22: =D22-F22 -> -55850 | H22: Actuals - Landis Report | I22: =K22+M22 -> 11262 | J22: =K22+M22 -> 11262 | K22: 2234 | L22: =K22/$C$6*$C$7*$C$8 -> 53.616 | M22: 9028 | N22: =M22/$C$6*$C$7*$C$8 -> 216.672 | O22: =E22-$E$21 -> 13.68 | Q22: =D22/K22 -> 0
A23: 2011 | C23: 390132 | D23: 648369 | E23: =L23+N23 -> 247.584 | F23: =K23*$C$4 -> 24450 | G23: =D23-F23 -> 623919 | H23: Actuals - Landis Report | I23: =K23+M23 -> 10316 | J23: =K23+M23 -> 10316 | K23: 978 | L23: =K23/$C$6*$C$7*$C$8 -> 23.472 | M23: 9338 | N23: =M23/$C$6*$C$7*$C$8 -> 224.112 | O23: =E23-$E$21 -> -9.024 | P23: =C23/M23 -> 41.778968 | Q23: =D23/K23 -> 662.95399
A24: 2010 | C24: 321788 | D24: 541079 | E24: =L24+N24 -> 240.576 | F24: =K24*$C$4 -> 18350 | G24: =D24-F24 -> 522729 | H24: Actuals - Landis Report | I24: =K24+M24 -> 10024 | J24: =K24+M24 -> 10024 | K24: 734 | L24: =K24/$C$6*$C$7*$C$8 -> 17.616 | M24: 9290 | N24: =M24/$C$6*$C$7*$C$8 -> 222.96 | O24: =E24-$E$21 -> -16.032 | P24: =C24/M24 -> 34.638105 | Q24: =D24/K24 -> 737.16485
A25: 2009 | B25: CEMEX settles with State of Colorado for $600K and Air Quality Improvements | C25: 281906 | D25: 463398 | E25: =L25+N25 -> 235.176 | F25: =K25*$C$4 -> 9800 | G25: =D25-F25 -> 453598 | H25: Actuals - Landis Report | I25: =K25+M25 -> 9799 | J25: =K25+M25 -> 9799 | K25: 392 | L25: =K25/$C$6*$C$7*$C$8 -> 9.408 | M25: 9407 | N25: =M25/$C$6*$C$7*$C$8 -> 225.768 | O25: =E25-$E$21 -> -21.432 | P25: =C25/M25 -> 29.967684 | Q25: =D25/K25 -> 1182.1378
A26: 2008 | C26: 311302 | D26: 501317 | E26: =L26+N26 -> 427.32 | F26: =K26*$C$4 -> 25875 | G26: =D26-F26 -> 475442 | H26: Actuals - Landis Report | I26: =K26+M26 -> 17805 | J26: =K26+M26 -> 17805 | K26: 1035 | L26: =K26/$C$6*$C$7*$C$8 -> 24.84 | M26: 16770 | N26: =M26/$C$6*$C$7*$C$8 -> 402.48 | O26: =E26-$E$21 -> 170.712 | P26: =C26/M26 -> 18.563029 | Q26: =D26/K26 -> 484.36425
A27: 2007 | B27: Department of Justice and EPA Sue CEMEX for "Major Modifications" - $10M Expansion Project | C27: 479225 | D27: 788780 | E27: =L27+N27 -> 504.192 | F27: =K27*$C$4 -> 23750 | G27: =D27-F27 -> 765030 | H27: Actuals - Landis Report | I27: =K27+M27 -> 21008 | J27: =K27+M27 -> 21008 | K27: 950 | L27: =K27/$C$6*$C$7*$C$8 -> 22.8 | M27: 20058 | N27: =M27/$C$6*$C$7*$C$8 -> 481.392 | O27: =E27-$E$21 -> 247.584 | P27: =C27/M27 -> 23.891963 | Q27: =D27/K27 -> 830.29474
A28: 2006 | B28: State of Colorado Files Action | C28: 466173 | D28: 734456 | E28: =L28+N28 -> 466.344 | F28: =K28*$C$4 -> 23875 | G28: =D28-F28 -> 710581 | H28: Actuals - Landis Report | I28: =K28+M28 -> 19431 | J28: =K28+M28 -> 19431 | K28: 955 | L28: =K28/$C$6*$C$7*$C$8 -> 22.92 | M28: 18476 | N28: =M28/$C$6*$C$7*$C$8 -> 443.424 | O28: =E28-$E$21 -> 209.736 | P28: =C28/M28 -> 25.231273 | Q28: =D28/K28 -> 769.06387
A29: 2005 | C29: 440384 | D29: 739260 | E29: =L29+N29 -> 439.207 | F29: =$C$4*K29 -> 25000 | G29: =D29-F29 -> 714260 | H29: Landis Report | I29: Missing | J29: =K29+M29 -> 18615.36 | K29: 1000 | L29: =K29/365*2*3 -> 16.438356 | M29: =C29/$C$5 -> 17615.36 | N29: =M29/$C$6*$C$7*$C$8 -> 422.76864 | O29: =E29-$E$21 -> 182.599 | P29: =C29/M29 -> 25 | Q29: =D29/K29 -> 739.26
A30: 2004 | C30: 472053 | D30: 791866 | E30: =L30+N30 -> 469.60924 | F30: =$C$4*K30 -> 25000 | G30: =D30-F30 -> 766866 | H30: Landis Report | I30: Missing | J30: =K30+M30 -> 19882.12 | K30: 1000 | L30: =K30/365*2*3 -> 16.438356 | M30: =C30/$C$5 -> 18882.12 | N30: =M30/$C$6*$C$7*$C$8 -> 453.17088 | O30: =E30-$E$21 -> 213.00124 | P30: =C30/M30 -> 25 | Q30: =D30/K30 -> 791.866
A31: 2003 | C31: 516251 | D31: 830428 | E31: =L31+N31 -> 512.03932 | F31: =$C$4*K31 -> 25000 | G31: =D31-F31 -> 805428 | H31: Landis Report | I31: Missing | J31: =K31+M31 -> 21650.04 | K31: 1000 | L31: =K31/365*2*3 -> 16.438356 | M31: =C31/$C$5 -> 20650.04 | N31: =M31/$C$6*$C$7*$C$8 -> 495.60096 | O31: =E31-$E$21 -> 255.43132 | P31: =C31/M31 -> 25 | Q31: =D31/K31 -> 830.428
A32: 2002 | C32: 472945 | D32: 736289 | E32: =L32+N32 -> 470.46556 | F32: =$C$4*K32 -> 25000 | G32: =D32-F32 -> 711289 | H32: Landis Report | I32: Missing | J32: =K32+M32 -> 19917.8 | K32: 1000 | L32: =K32/365*2*3 -> 16.438356 | M32: =C32/$C$5 -> 18917.8 | N32: =M32/$C$6*$C$7*$C$8 -> 454.0272 | O32: =E32-$E$21 -> 213.85756 | P32: =C32/M32 -> 25 | Q32: =D32/K32 -> 736.289
A33: 2001 | B33: Article in Cement Review about Expansion Project and New Oxygen Tanks | C33: 508733 | D33: 760801 | E33: =L33+N33 -> 504.82204 | F33: =$C$4*K33 -> 25000 | G33: =D33-F33 -> 735801 | H33: Landis Report | I33: Missing | J33: =K33+M33 -> 21349.32 | K33: 1000 | L33: =K33/365*2*3 -> 16.438356 | M33: =C33/$C$5 -> 20349.32 | N33: =M33/$C$6*$C$7*$C$8 -> 488.38368 | O33: =E33-$E$21 -> 248.21404 | P33: =C33/M33 -> 25 | Q33: =D33/K33 -> 760.801
A34: 2000 | B34: $10M Plant Expansion Project Ongoing; CEMEX Acquires Facility from Southdown | C34: 541747 | D34: 846129 | E34: =L34+N34 -> 536.51548 | F34: =$C$4*K34 -> 25000 | G34: =D34-F34 -> 821129 | H34: Landis Report | I34: Missing | J34: =K34+M34 -> 22669.88 | K34: 1000 | L34: =K34/365*2*3 -> 16.438356 | M34: =C34/$C$5 -> 21669.88 | N34: =M34/$C$6*$C$7*$C$8 -> 520.07712 | O34: =E34-$E$21 -> 279.90748 | P34: =C34/M34 -> 25 | Q34: =D34/K34 -> 846.129
A35: 1999 | B35: $10M Plant Expansion Project Ongoing | C35: 500031 | D35: 845049 | E35: =L35+N35 -> 496.46812 | F35: =$C$4*K35 -> 25000 | G35: =D35-F35 -> 820049 | H35: Landis Report | I35: Missing | J35: =K35+M35 -> 21001.24 | K35: 1000 | L35: =K35/365*2*3 -> 16.438356 | M35: =C35/$C$5 -> 20001.24 | N35: =M35/$C$6*$C$7*$C$8 -> 480.02976 | O35: =E35-$E$21 -> 239.86012 | P35: =C35/M35 -> 25 | Q35: =D35/K35 -> 845.049
A36: 1998 | B36: $10M Plant Expansion Project Begins | C36: 501008 | D36: 826631 | E36: =L36+N36 -> 497.40604 | F36: =$C$4*K36 -> 25000 | G36: =D36-F36 -> 801631 | H36: Landis Report | I36: Missing | J36: =K36+M36 -> 21040.32 | K36: 1000 | L36: =K36/365*2*3 -> 16.438356 | M36: =C36/$C$5 -> 20040.32 | N36: =M36/$C$6*$C$7*$C$8 -> 480.96768 | O36: =E36-$E$21 -> 240.79804 | P36: =C36/M36 -> 25 | Q36: =D36/K36 -> 826.631
A37: 1997 | B37: Dowe Flats Starts Producing Material and Transports via Conveyor over Highway 66 | C37: 458694 | E37: =L37+N37 -> 456.7846 | F37: =$C$4*K37 -> 25000 | G37: 100000 | H37: Landis Report | I37: Missing | J37: =K37+M37 -> 19347.76 | K37: 1000 | L37: =K37/365*2*3 -> 16.438356 | M37: =C37/$C$5 -> 18347.76 | N37: =M37/$C$6*$C$7*$C$8 -> 440.34624 | O37: =E37-$E$21 -> 200.1766 | P37: =C37/M37 -> 25 | Q37: =D37/K37 -> 0
A38: 1996 | B38: Larimer Pits last shipment Jan 1997 | C38: 430272 | D38: 754404 | E38: =L38+N38 -> 429.49948 | F38: =$C$4*K38 -> 25000 | G38: =D38-F38 -> 729404 | H38: Landis Report | I38: Missing | J38: =K38+M38 -> 18210.88 | K38: 1000 | L38: =K38/365*2*3 -> 16.438356 | M38: =C38/$C$5 -> 17210.88 | N38: =M38/$C$6*$C$7*$C$8 -> 413.06112 | O38: =E38-$E$21 -> 172.89148 | P38: =C38/M38 -> 25 | Q38: =D38/K38 -> 754.404
A39: 1995 | C39: 425274 | D39: 735768 | E39: =L39+N39 -> 424.7014 | F39: =$C$4*K39 -> 25000 | G39: =D39-F39 -> 710768 | H39: Landis Report | I39: Missing | J39: =K39+M39 -> 18010.96 | K39: 1000 | L39: =K39/365*2*3 -> 16.438356 | M39: =C39/$C$5 -> 17010.96 | N39: =M39/$C$6*$C$7*$C$8 -> 408.26304 | O39: =E39-$E$21 -> 168.0934 | P39: =C39/M39 -> 25 | Q39: =D39/K39 -> 735.768
A40: 1994 | B40: CEMEX Lyons becomes a Nonconforming Use as Boulder County Land Use Code is Adopted - October 18th, 1994 | C40: 418505 | D40: 748065 | E40: =L40+N40 -> 456.23424 | F40: 56739 | G40: =D40-F40 -> 691326 | H40: Landis Report | I40: Missing | J40: =K40+M40 -> 19009.76 | K40: =F40/$C$4 -> 2269.56 | L40: =K40/$C$6*$C$7*$C$8 -> 54.46944 | M40: =C40/$C$4 -> 16740.2 | N40: =M40/$C$6*$C$7*$C$8 -> 401.7648 | O40: =E40-$E$21 -> 199.62624 | P40: =C40/M40 -> 25 | Q40: =D40/K40 -> 329.60794
A41: 1993 | B41: Lyons Quarry, Pit E, South of Hygiene Road, Ceases Operation - July 1993 Dowe Flats Application Begins | C41: 419230 | D41: =C41*$C$3+$D$3 -> 678840.06 | E41: =L41+N41 -> 578.76768 | F41: 183653 | G41: =D41-F41 -> 495187.06 | H41: Calculated - Landis Report | I41: 30716 | J41: =K41+M41 -> 24115.32 | K41: =F41/$C$4 -> 7346.12 | L41: =K41/$C$6*$C$7*$C$8 -> 176.30688 | M41: =C41/$C$4 -> 16769.2 | N41: =M41/$C$6*$C$7*$C$8 -> 402.4608 | O41: =E41-$E$21 -> 322.15968 | P41: =C41/M41 -> 25 | Q41: =D41/K41 -> 92.407973
A42: 1992 | C42: 403670 | D42: =C42*$C$3+$D$3 -> 653930.05 | E42: =L42+N42 -> 486.15334 | F42: =6000*25 -> 150000 | G42: =D42-F42 -> 503930.05 | H42: Calculated - Landis Report | I42: 29448 | J42: =K42+M42 -> 22146.8 | K42: =F42/$C$4 -> 6000 | L42: =K42/365*2*3 -> 98.630137 | M42: =C42/$C$4 -> 16146.8 | N42: =M42/$C$6*$C$7*$C$8 -> 387.5232
...

Sheet Volunteers
C2: Name | D2: Email | E2: Background
C3: Bart Lorang | D3: lorangb@gmail.com | E3: Deep Diving on CEMEX Issues for 3 years, understand the history. Colorado State "Mathlete" in High School, Engineering Degree (Computer Science)
C4: Sarah Lorang | D4: sarah@goodneighborslyons.com | E4: Good Neighbors Leader
C5: James Silvestro | D5: jsilvestro@irelandstapleton.com | E5: Ireland & Stapleton Land Use Attorney, Victories in Boulder County against Martin Marietta in the St Vrain Valley
C6: Kit Fuller | D6: fullerhkit@yahoo.com | E6: Website Traffic Analysis
C7: Lenson Pellouchoud | D7: lensonp@gmail.com | E7: PhD in Materials Engineering, Family in Lyons
C8: Molly Hardman | D8: w0mom.molly@gmail.com | E8: Lives nearby and is a scientist at CU
C9: Judy Koslov | D9: judykoslov@gmail.com | E9: Was involved in St Vrain Watch Dogs
C10: Debbie Scott | D10: dscott@townoflyons.com | E10: Former CDOT project manager & Engineer
C11: Fred Annexstein | D11: fannexstein@gmail.com | E11: PhD in Computer Science, Volunteered Son-In Law, Jake Holdern who is a research in traffic and energy modeling at NREL
C12: Jim Franklin | D12: jim.h.franklin@gmail.com | E12: JD/MBA - EIR for Master Program at School of Mines
C13: Stephen Dalton | D13: stephen.g.dalton@gmail.com | E13: Father is retired civil engineer who worked for big transporation firms in NYC
C14: Yoav Lurie | D14: yoavlurie@gmail.com | E14: Roommate is a professional traffic engineer, not licensed in CO but take a look
C15: Mike Cubison | D15: mike.cubison@gmail.com
C16: Scott Wolf | D16: ymscott.wolf@gmail.com | E16: Crunching data and drawing observations

Sheet Issues List
B2: Issue # | C2: Status | D2: Who Owns | E2: Type
C3: Done | D3: Bart Lorang | E3: Research & Analysis | F3: Compile an Initial data archive from the various records
C4: Done | D4: Sarah Lorang | E4: Research | F4: Compile all of CEMEX officials statements from 2022 hearings warning the community that traffic would increase
C5: Done | D5: James Silvestro | E5: Legal | F5: Craft the Legal Letter and Argument to Boulder County
C6: Done | D6: Scott Wolf | E6: Research & Analysis | F6: Fill in all the gaps in the data back to 1993 (or earlier) and check Bart's data compilation - make sure we have the underlying facts correct!
C7: In Progress | D7: Scott Wolf | E7: Research & Analysis | F7: Instances where Landis data is suspect or inconsistent with CDPHE data
E8: Research & Analysis | F8: Find out the 2023 and 2024 Trucking and Actual figures that CEMEX is withholding (CDPHE engaged in another compliance matter? CORA request?)
C9: In Progress | D9: Mike Cubison & Scott Wolf | E9: Mathematics | F9: Develop our own regression equation(s) to compute truck traffic that are superior to the "N=4" regression equation developed by Landis
E10: Research & Analysis | F10: Examine the CDOT data in the Landis report and cross check against other data sources
D11: Judy Koslov | E11: Logic | F11: Find anomalies in the Landis data and/or calculations
D12: Judy Koslov | E12: Logic | F12: Demonstrate that the 2023 'Calculations' are inappropriate to use given the operational changes in 1994, 1997, 2018 & 2022
E13: Narrative & Writing | F13: Visually illustrate 40 years worth of information in a simple, accessible way that tells the story
D14: Bart (authoring) Kit (editing) | E14: Narrative & Writing | F14: Develop a formal Engineering report to accompany our conclusion
C15: In Progress | D15: Scott | E15: Synthesis | F15: Compile all the reasons that the Landis report is flawed statistically and/or logically, developed to present a favorable conclusion for their client
